Workbook

Sheet 2025年度実績確認
A1: 2025年度実績 | B1: 2025/03/01 - 2026/02/28 | E1: 目的：前年度実績を元に目安となる流入数や各リードステージへの転換率を把握する
B3: 流入数 （セッション数） | C3: MQL化率 （CVR） | D3: MQL数 （CV数・個人情報獲得数） | E3: SAL化率 | F3: SAL数 （営業受け入れ数） | G3: SQL化率 | H3: SQL数 （商談数） | I3: MQLに対するSQL化率 | J3: 受注率 | K3: 受注件数
A4: UN | B4: 35135 | C4: =D4/B4 -> 0.0075707983 | D4: 266 | E4: =F4/D4 -> 0.19924812 | F4: 53 | G4: =H4/F4 -> 0.8490566 | H4: 45 | I4: =H4/D4 -> 0.16917293 | J4: =K4/H4 -> 0.13333333 | K4: 6
A5: SCH | B5: 23896 | C5: =D5/B5 -> 0.0016320723 | D5: 39 | E5: =F5/D5 -> 0.17948718 | F5: 7 | G5: =H5/F5 -> 1 | H5: 7 | I5: =H5/D5 -> 0.17948718 | J5: =K5/H5 -> 0.42857143 | K5: 3
A6: MED | B6: 35593 | C6: =D6/B6 -> 0.0096086309 | D6: 342 | E6: =F6/D6 -> 0.20175439 | F6: 69 | G6: =H6/F6 -> 0.2173913 | H6: 15 | I6: =H6/D6 -> 0.043859649 | J6: =K6/H6 -> 0.2 | K6: 3
A7: IS | B7: 17505 | C7: =D7/B7 -> 0.010968295 | D7: 192 | E7: =F7/D7 -> 0.16666667 | F7: 32 | G7: =H7/F7 -> 0.21875 | H7: 7 | I7: =H7/D7 -> 0.036458333 | J7: =K7/H7 -> 0 | K7: 0
A8: 計 | B8: =SUM(B4:B7) -> 112129 | C8: =D8/B8 -> 0.0074824532 | D8: =SUM(D4:D7) -> 839 | E8: =F8/D8 -> 0.19189511 | F8: =SUM(F4:F7) -> 161 | G8: =H8/F8 -> 0.45962733 | H8: =SUM(H4:H7) -> 74 | I8: =H8/D8 -> 0.088200238 | J8: =K8/H8 -> 0.16216216 | K8: =SUM(K4:K7) -> 12
A10: 寄与する指標 | B10: SEO強化 | C10: CTA改善 | E10: MQL定義の明確化（業種・規模・興味関心度） | G10: 初回接触速度改善 | J10: ターゲット制度改善
B11: 広告運用 | C11: LP改善 | E11: スコアリング導入/改善 | G11: 営業フォロー率改善 | J11: 提案資料の標準化
B12: ウェビナー・イベント | C12: フォーム改善 | E12: フォーム項目改善 | G12: 商談化条件の明確化 | J12: 事例コンテンツの営業活用
B13: SNS・オウンドメディア | C13: ホワイトペーパー / 事例などオファー強化 | E13: ナーチャリング施策（メール育成・セミナー・事例） | G13: 失注理由管理 | J13: 競合比較資料
B14: メールマガジンによる再訪喚起 | C14: ターゲティング改善 | E14: ホットリード通知 | G14: 再ナーチャリング導線 | J14: 業界別提案テンプレート
B15: PR/記事露出 | C15: 導線改善 | J15: 失注理由分析
B16: リファラル導線強化 | J16: 勝ち筋案件の横展開
D22: 実績 | I22: 目標
B23: 全体 | C23: UN | D23: SCH | E23: MED | F23: IS | G23: 全体 | H23: UN | I23: SCH | J23: MED | K23: IS
A24: 年度 | B24: 2025 | C24: 2025 | D24: 2025 | E24: 2025 | F24: 2025 | G24: 2026 | H24: 2026 | I24: 2026 | J24: 2026 | K24: 2026
A25: 売上目標
A26: マーケ起点売上比率目標 | B26: 0.1 | C26: 0.1 | D26: 0.1 | E26: 0.1 | F26: 0.1 | G26: 0.1 | H26: 0.1 | I26: 0.1 | J26: 0.1 | K26: 0.1
A27: マーケ起点売上目標
A28: 平均受注単価
A29: 必要受注件数 | B29: 12 | C29: 6 | D29: 3 | E29: 3 | F29: 0 | G29: =SUM(H29:K29) -> 27 | H29: 8 | I29: 5 | J29: 10 | K29: 4
A30: 受注率計画 | B30: =B29/B31 -> 0.16216216 | C30: =C29/C31 -> 0.13333333 | D30: =D29/D31 -> 0.42857143 | E30: =E29/E31 -> 0.2 | F30: =F29/F31 -> 0 | G30: =AVERAGE(H30:K30) -> 0.28333333 | H30: =H29/H31 -> 0.13333333 | I30: =I29/I31 -> 0.33333333 | J30: =J29/J31 -> 0.33333333 | K30: =K29/K31 -> 0.33333333
A31: 必要SQL数 | B31: 74 | C31: 45 | D31: 7 | E31: 15 | F31: 7 | G31: =SUM(H31:K31) -> 117 | H31: 60 | I31: 15 | J31: 30 | K31: 12
A32: SQL化率計画 | B32: =B31/B33 -> 0.45962733 | C32: =C31/C33 -> 0.8490566 | D32: =D31/D33 -> 1 | E32: =E31/E33 -> 0.2173913 | F32: =F31/F33 -> 0.21875 | G32: =AVERAGE(H32:K32) -> 0.57129948 | H32: 0.8490566 | I32: 1 | J32: 0.2173913 | K32: 0.21875
A33: 必要SAL数 | B33: 161 | C33: 53 | D33: 7 | E33: 69 | F33: 32 | G33: =SUM(H33:K33) -> 278.52381 | H33: =H31/H32 -> 70.666667 | I33: =I31/I32 -> 15 | J33: =J31/J32 -> 138 | K33: =K31/K32 -> 54.857143
A34: SAL化率計画 | B34: =B33/B35 -> 0.19189511 | C34: =C33/C35 -> 0.19924812 | D34: =D33/D35 -> 0.17948718 | E34: =E33/E35 -> 0.20175439 | F34: =F33/F35 -> 0.16666667 | G34: =AVERAGE(H34:K34) -> 0.23881643 | H34: =H33/H35 -> 0.23555556 | I34: =I33/I35 -> 0.21428571 | J34: =J33/J35 -> 0.30666667 | K34: =K33/K35 -> 0.19875776
A35: 必要MQL数 | B35: 839 | C35: 266 | D35: 39 | E35: 342 | F35: 192 | G35: =SUM(H35:K35) -> 1096 | H35: 300 | I35: 70 | J35: 450 | K35: 276
A36: MQL化率計画 | B36: =B35/B37 -> 0.0074824532 | C36: =C35/C37 -> 0.0075707983 | D36: =D35/D37 -> 0.0016320723 | E36: =E35/E37 -> 0.0096086309 | F36: =F35/F37 -> 0.010968295 | G36: =AVERAGE(H36:K36) -> 0.0074449491 | H36: 0.0075707983 | I36: 0.0016320723 | J36: 0.0096086309 | K36: 0.010968295 | N36: ↓元式
A37: 必要流入数 | B37: 112129 | C37: 35135 | D37: 23896 | E37: 35593 | F37: 17505 | G37: =SUM(H37:K37) -> 154512.53 | H37: =H35/H36 -> 39625.94 | I37: =I35/I36 -> 42890.256 | J37: =J35/J36 -> 46832.895 | K37: =K35/K36 -> 25163.438 | N37: =N35/N36 -> #VALUE!
A38: Organic | C38: 16558 | D38: 14913 | E38: 20571 | F38: 3123 | H38: =(H$37-SUM(H$40,H$41,H$44))*C38/SUM(C$38,C$39,C$42,C$43) -> 18717.014 | I38: =(I$37-SUM(I$39,I$41,I$44))*D38/SUM(D$38,D$40,D$42,D$43) -> 28542.521 | J38: =(J$37-SUM(J$40,J$41,J$44))*E38/SUM(E$38,E$39,E$42,E$43) -> 28944.683 | K38: =(K$37-SUM(K$39,K$41,K$44))*F38/SUM(F$38,F$40,F$42,F$43) -> 5649.71 | N38: =N36*(I38/I37) -> #VALUE!
A39: Paid | C39: 7612 | D39: 0 | E39: 5287 | F39: 1155 | H39: =(H$37-SUM(H$40,H$41,H$44))*C39/SUM(C$38,C$39,C$42,C$43) -> 8604.536 | I39: 0 | J39: =(J$37-SUM(J$40,J$41,J$44))*E39/SUM(E$38,E$39,E$42,E$43) -> 7439.1394 | K39: 1155 | N39: 1155
A40: Display | C40: 0 | D40: =2947+494 -> 3441 | E40: 1652 | F40: =979+835 -> 1814 | H40: 0 | I40: =(I$37-SUM(I$39,I$41,I$44))*D40/SUM(D$38,D$40,D$42,D$43) -> 6585.8523 | J40: 1652 | K40: =(K$37-SUM(K$39,K$41,K$44))*F40/SUM(F$38,F$40,F$42,F$43) -> 3281.6439 | N40: =N36*(I41/I37) -> #VALUE!
A41: Direct | C41: 7528 | D41: 4146 | E41: 3976 | F41: 6469 | H41: 7528 | I41: 4146 | J41: 3976 | K41: 6469 | N41: 6469
A42: Email | C42: 2426 | D42: 480 | E42: 633 | F42: 3379 | H42: =(H$37-SUM(H$40,H$41,H$44))*C42/SUM(C$38,C$39,C$42,C$43) -> 2742.3285 | I42: =(I$37-SUM(I$39,I$41,I$44))*D42/SUM(D$38,D$40,D$42,D$43) -> 918.68907 | J42: =(J$37-SUM(J$40,J$41,J$44))*E42/SUM(E$38,E$39,E$42,E$43) -> 890.67056 | K42: =(K$37-SUM(K$39,K$41,K$44))*F42/SUM(F$38,F$40,F$42,F$43) -> 6112.8306 | N42: =N36*(I42/I37) -> #VALUE!
A43: Referral | C43: 1565 | D43: =1735-494 -> 1241 | E43: 1841 | F43: =1944-835 -> 1109 | H43: =(H$37-SUM(H$40,H$41,H$44))*C43/SUM(C$38,C$39,C$42,C$43) -> 1769.0619 | I43: =(I$37-SUM(I$39,I$41,I$44))*D43/SUM(D$38,D$40,D$42,D$43) -> 2375.194 | J43: =(J$37-SUM(J$40,J$41,J$44))*E43/SUM(E$38,E$39,E$42,E$43) -> 2590.4021 | K43: =(K$37-SUM(K$39,K$41,K$44))*F43/SUM(F$38,F$40,F$42,F$43) -> 2006.2531 | N43: 1944
A44: other | C44: 265 | D44: 322 | E44: 1340 | F44: 489 | H44: 265 | I44: 322 | J44: 1340 | K44: 489 | N44: 489
B46: 施策により可変な数値 | I46: 2025実績
A47: Organic | B47: SEO対策 | C47: LLMO対策 | D47: 内部リンク最適化 | E47: プレスリリース
A48: Paid | B48: ※代理店
...

Sheet UN｜KPIツリー（構造確認用）
A1: KPIツリー（構成イメージ）
A2: サンプル：UN 2025実績&2026目標 | H2: KPIツリー（Miro）
H3: https://miro.com/app/board/uXjVHZpxzbo=/
I4: 目標値
I5: 前年実績
I6: 施策により可変な数値
B8: ※マーケ起点 | R8: Organic | Z8: 施策例 | AF8: 月次目標（1/12）
B9: 受注件数 | E9: SQL数 | H9: SAL数 | K9: MQL数 | N9: 必要セッション数 | P9: =SUM(R9,R27,R38,R42,R46,R58) -> 0.99331246 | R9: =S10/$N$10 -> 0.47234245 | S9: 必要セッション数 | T9: MQL数 | U9: MQL数 | V9: CVR | W9: TOP｜/ | X9: 必要セッション数 | Y9: セッション数 | Z9: 掲載本数（ボリューム） | AE9: =R8 -> Organic | AF9: =S10/12 -> 1559.7511
B10: ='2025年度実績確認'!H29 -> 8 | E10: ='2025年度実績確認'!H31 -> 60 | H10: ='2025年度実績確認'!H33 -> 70.666667 | K10: ='2025年度実績確認'!H35 -> 300 | N10: =K10/N28 -> 39625.94 | P10: =SUM(S10,S28,S39,S43,S47,S59) -> 39360.94 | S10: ='2025年度実績確認'!H38 -> 18717.014 | T10: =(K$10-SUM(U$39,U$43,U$70))*U10/SUM(U$10,U$28,U$47,U$59) -> 78.97076 | U10: 64 | V10: =IF(S10=0,0,U10/S10) -> 0.0034193489 | X10: =(S$10-Y$22)*Y10/SUM(Y$16,Y$13,Y$19,Y$10) -> 6924.0248 | Y10: 5888 | Z10: SEO・AIO対策 | AE10: =R26 -> Paid | AF10: =S28/12 -> 717.04467
B11: 目標値 | E11: 目標値 | H11: SQL数/SQL化率 | K11: 目標値 | N11: MQL数/CVR | P11: =P10-N10 -> -265 | S11: 前年実績セッション数/可変チャネルの前年実績合計セッション数×可変チャネル必要流入数 | T11: 目安値 | U11: 前年実績 | V11: 前年実績 | X11: 前年実績セッション数/可変施策の前年実績合計セッション数×必要セッション数（チャネルごと） | Y11: 前年実績 | Z11: 検索ニーズ起点の記事制作 | AE11: =R37 -> Display
W12: 事例｜case | X12: 必要セッション数 | Y12: セッション数 | Z12: 業界別事例 | AE12: =R41 -> Direct | AF12: =S43/12 -> 627.33333
E13: 受注率 | H13: SQL化率 | K13: SAL化率 | X13: =(S$10-Y$22)*Y13/SUM(Y$16,Y$13,Y$19,Y$10) -> 4893.15 | Y13: 4161 | Z13: 検索ニーズ起点のLP制作 | AE13: =R45 -> Email | AF13: =S47/12 -> 228.52737
E14: =B10/E10 -> 0.13333333 | H14: =E10/H10 -> 0.8490566 | K14: =H10/K10 -> 0.23555556 | X14: 前年実績セッション数/可変施策の前年実績合計セッション数×必要セッション数（チャネルごと） | Y14: 前年実績 | Z14: TOPページ改善 | AE14: =R57 -> Referral | AF14: =S59/12 -> 147.42182
E15: 受注件数/SQL数 | H15: 前年実績 | K15: SAL数/MQL数 | W15: コラム｜column,colmun | X15: 必要セッション数 | Y15: セッション数 | AE15: Other | AF15: =S70/12 -> 22.083333
X16: =(S$10-Y$22)*Y16/SUM(Y$16,Y$13,Y$19,Y$10) -> 4011.1835 | Y16: 3411
X17: 前年実績セッション数/可変施策の前年実績合計セッション数×必要セッション数（チャネルごと） | Y17: 前年実績
W18: LP｜office,service,work | X18: 必要セッション数 | Y18: セッション数
X19: =(S$10-Y$22)*Y19/SUM(Y$16,Y$13,Y$19,Y$10) -> 652.65519 | Y19: =176+70+309 -> 555
X20: 前年実績セッション数/可変施策の前年実績合計セッション数×必要セッション数（チャネルごと） | Y20: 前年実績
W21: その他｜reasons,news,company,document,フォーム,その他 | X21: 必要セッション数 | Y21: セッション数
X22: 2236 | Y22: =16251-SUM(Y10,Y19,Y13,Y16) -> 2236
X23: 前年実績 | Y23: 前年実績
W24: FAQページ
W25: 内部リンク | Z25: 回遊導線整備
R26: Paid
N27: CVR | O27: 事例 | R27: =S28/$N$10 -> 0.21714402 | S27: 必要セッション数 | T27: MQL数 | U27: MQL数 | V27: CVR | W27: TOP｜/ | X27: 必要セッション数 | Y27: セッション数 | Z27: TOPページ改善
N28: ='2025年度実績確認'!H36 -> 0.0075707983 | O28: WP追加 | S28: ='2025年度実績確認'!H39 -> 8604.536 | T28: =(K$10-SUM(U$39,U$43,U$70))*U28/SUM(U$10,U$28,U$47,U$59) -> 83.906433 | U28: 68 | V28: =IF(S28=0,0,U28/S28) -> 0.0079028085 | X28: =(S$28-Y$34)*Y28/SUM(Y$28,Y$31) -> 5036.3284 | Y28: 4300 | Z28: クリエイティブ改善
N29: 前年実績 | O29: フォーム最適化 | S29: 前年実績セッション数/可変チャネルの前年実績合計セッション数×可変チャネル必要流入数 | T29: 目安値 | U29: 前年実績 | V29: 前年実績 | X29: 前年実績セッション数/可変施策の前年実績合計セッション数×必要セッション数（チャネルごと） | Y29: 前年実績 | Z29: キーワード拡張
W30: LP｜office,service,work | X30: 必要セッション数 | Y30: セッション数 | Z30: ターゲティング改善
X31: =(S$28-Y$34)*Y31/SUM(Y$28,Y$31) -> 2956.2076 | Y31: =249+1710+565 -> 2524 | Z31: LP制作・改善
X32: 前年実績セッション数/可変施策の前年実績合計セッション数×必要セッション数（チャネルごと） | Y32: 前年実績
W33: その他｜case,column,reasons,news,company,document,フォーム,その他 | X33: 必要セッション数 | Y33: セッション数
X34: 612 | Y34: =7436-SUM(Y28,Y31) -> 612
X35: 前年実績 | Y35: 前年実績
R37: Display
R38: =S39/$N$10 -> 0 | S38: 必要セッション数 | T38: MQL数 | U38: MQL数 | V38: CVR | W38: ※再訪喚起につながる改善
S39: ='2025年度実績確認'!H40 -> 0 | T39: =K$10*U39/SUM(U$10,U$28,U$39,U$43,U$47,U$59,U$70) -> 0 | U39: 0 | V39: =IF(S39=0,0,U39/S39) -> 0
S40: 前年実績 | T40: 目安値 | U40: 前年実績 | V40: 前年実績
R41: Direct
R42: =S43/$N$10 -> 0.18997657 | S42: 必要セッション数 | T42: MQL数 | U42: MQL数 | V42: CVR | W42: ※ブランディング（ブランド想起・再訪喚起）
...

Sheet SCH｜KPIツリー（構造確認用）
A1: KPIツリー（構成イメージ）
A2: サンプル：SCH 2025実績&2026目標 | H2: KPIツリー（Miro）
H3: https://miro.com/app/board/uXjVHZpxzbo=/
I4: 目標値
I5: 前年実績
I6: 施策により可変な数値
B8: ※マーケ起点 | R8: Organic | Z8: 施策例
B9: 受注件数 | E9: SQL数 | H9: SAL数 | K9: MQL数 | N9: 必要セッション数 | P9: =SUM(R9,R27,R38,R48,R52,R64) -> 0.99249247 | R9: =S10/$N$10 -> 0.66547798 | S9: 必要セッション数 | T9: MQL数 | U9: MQL数 | V9: CVR | W9: TOP｜/ | X9: 必要セッション数 | Y9: セッション数 | Z9: 掲載本数（ボリューム）
B10: ='2025年度実績確認'!I29 -> 5 | E10: ='2025年度実績確認'!I31 -> 15 | H10: ='2025年度実績確認'!I33 -> 15 | K10: ='2025年度実績確認'!I35 -> 70 | N10: =K10/N28 -> 42890.256 | P10: =SUM(S10,S28,S39,S49,S53,S65) -> 42568.256 | S10: ='2025年度実績確認'!I38 -> 28542.521 | T10: =(K$10-SUM(U$28,U$49,U$76))*U10/SUM(U$10,U$39,U$53,U$65) -> 25.826087 | U10: 11 | V10: =IF(S10=0,0,U10/S10) -> 0.00038538992 | X10: =(S$10-Y$22)*Y10/SUM(Y$16,Y$13,Y$19,Y$10) -> 5300.3676 | Y10: 2472 | Z10: SEO・AIO対策
B11: 目標値 | E11: 目標値 | H11: SQL数/SQL化率 | K11: 目標値 | N11: MQL数/CVR | P11: =P10-N10 -> -322 | S11: 前年実績セッション数/可変チャネルの前年実績合計セッション数×可変チャネル必要流入数 | T11: 目安値 | U11: 前年実績 | V11: 前年実績 | X11: 前年実績セッション数/可変施策の前年実績合計セッション数×必要セッション数（チャネルごと） | Y11: 前年実績 | Z11: 検索ニーズ起点の記事制作
W12: 事例｜case | X12: 必要セッション数 | Y12: セッション数 | Z12: 業界別事例
E13: 受注率 | H13: SQL化率 | K13: SAL化率 | X13: =(S$10-Y$22)*Y13/SUM(Y$16,Y$13,Y$19,Y$10) -> 10131.164 | Y13: 4725 | Z13: 検索ニーズ起点のLP制作
E14: =B10/E10 -> 0.33333333 | H14: =E10/H10 -> 1 | K14: =H10/K10 -> 0.21428571 | X14: 前年実績セッション数/可変施策の前年実績合計セッション数×必要セッション数（チャネルごと） | Y14: 前年実績 | Z14: TOPページ改善
E15: 受注件数/SQL数 | H15: 前年実績 | K15: SAL数/MQL数 | W15: コラム｜column | X15: 必要セッション数 | Y15: セッション数
X16: =(S$10-Y$22)*Y16/SUM(Y$16,Y$13,Y$19,Y$10) -> 11930.115 | Y16: 5564
X17: 前年実績セッション数/可変施策の前年実績合計セッション数×必要セッション数（チャネルごと） | Y17: 前年実績
W18: LP｜targeting-lp | X18: 必要セッション数 | Y18: セッション数
X19: =(S$10-Y$22)*Y19/SUM(Y$16,Y$13,Y$19,Y$10) -> 27.874102 | Y19: 13
X20: 前年実績セッション数/可変施策の前年実績合計セッション数×必要セッション数（チャネルごと） | Y20: 前年実績
W21: その他｜reason,news,company,document,フォーム,その他 | X21: 必要セッション数 | Y21: セッション数
X22: 1153 | Y22: =13927-SUM(Y10,Y19,Y13,Y16) -> 1153
X23: 前年実績 | Y23: 前年実績
W24: FAQページ
W25: 内部リンク | Z25: 回遊導線整備
R26: Paid
N27: CVR | O27: 事例 | R27: =S28/$N$10 -> 0 | S27: 必要セッション数 | T27: MQL数 | U27: MQL数 | V27: CVR | W27: TOP｜/ | X27: 必要セッション数 | Y27: セッション数 | Z27: TOPページ改善
N28: ='2025年度実績確認'!I36 -> 0.0016320723 | O28: WP追加 | S28: ='2025年度実績確認'!I39 -> 0 | T28: 0 | U28: 2 | V28: =IF(S28=0,0,U28/S28) -> 0 | X28: =(S$28-Y$34)*Y28/SUM(Y$28,Y$31) -> #DIV/0! | Z28: クリエイティブ改善
N29: 前年実績 | O29: フォーム最適化 | S29: 前年実績 | T29: 目安値 | U29: 前年実績 | V29: 前年実績 | X29: 前年実績セッション数/可変施策の前年実績合計セッション数×必要セッション数（チャネルごと） | Y29: 前年実績 | Z29: キーワード拡張
W30: LP｜targeting-lp | X30: 必要セッション数 | Y30: セッション数 | Z30: ターゲティング改善
X31: =(S$28-Y$34)*Y31/SUM(Y$28,Y$31) -> #DIV/0! | Z31: LP制作・改善
X32: 前年実績セッション数/可変施策の前年実績合計セッション数×必要セッション数（チャネルごと） | Y32: 前年実績
W33: その他｜case,column,reason,news,company,document,フォーム,その他 | X33: 必要セッション数 | Y33: セッション数
X35: 前年実績 | Y35: 前年実績
R37: Display
R38: =S39/$N$10 -> 0.15355124 | S38: 必要セッション数 | T38: MQL数 | U38: MQL数 | V38: CVR | W38: TOP｜/ | X38: 必要セッション数 | Y38: セッション数 | Z38: TOPページ改善
S39: ='2025年度実績確認'!I40 -> 6585.8523 | T39: 2 | U39: 0 | V39: =IF(S39=0,0,U39/S39) -> 0 | X39: =(S$39-Y$45)*Y39/SUM(Y$39,Y$42) -> 3781.0355 | Y39: =570+1725 -> 2295 | Z39: クリエイティブ改善
S40: 前年実績セッション数/可変チャネルの前年実績合計セッション数×可変チャネル必要流入数 | T40: 目安値 | U40: 前年実績 | V40: 前年実績 | X40: 前年実績セッション数/可変施策の前年実績合計セッション数×必要セッション数（チャネルごと） | Y40: 前年実績 | Z40: キーワード拡張
W41: 事例｜case | X41: 必要セッション数 | Y41: セッション数 | Z41: ターゲティング改善
X42: =(S$39-Y$45)*Y42/SUM(Y$39,Y$42) -> 2767.8168 | Y42: =494+1186 -> 1680 | Z42: LP制作・改善
X43: 前年実績セッション数/可変施策の前年実績合計セッション数×必要セッション数（チャネルごと） | Y43: 前年実績
...

Sheet MED｜KPIツリー（構造確認用）
A1: KPIツリー（構成イメージ）
A2: サンプル：MED 2025実績&2026目標 | H2: KPIツリー（Miro）
H3: https://miro.com/app/board/uXjVHZpxzbo=/
I4: 目標値
I5: 前年実績
I6: 施策により可変な数値
B8: ※マーケ起点 | R8: Organic | Z8: 施策例
B9: 受注件数 | E9: SQL数 | H9: SAL数 | K9: MQL数 | N9: 必要セッション数 | P9: =SUM(R9,R24,R35,R39,R43,R55) -> 0.97138763 | R9: =S10/$N$10 -> 0.61804172 | S9: 必要セッション数 | T9: MQL数 | U9: MQL数 | V9: CVR | W9: TOP｜/ | X9: 必要セッション数 | Y9: セッション数 | Z9: 掲載本数（ボリューム）
B10: ='2025年度実績確認'!J29 -> 10 | E10: ='2025年度実績確認'!J31 -> 30 | H10: ='2025年度実績確認'!J33 -> 138 | K10: ='2025年度実績確認'!J35 -> 450 | N10: =K10/N25 -> 46832.895 | P10: =SUM(S10,S25,S36,S40,S44,S56) -> 45492.895 | S10: ='2025年度実績確認'!J38 -> 28944.683 | T10: =(K$10-SUM(U$36,U$40,U$67))*U10/SUM(U$10,U$25,U$44,U$56) -> 74.190647 | U10: 55 | V10: =IF(S10=0,0,U10/S10) -> 0.0019001763 | X10: =(S$10-Y$19)*Y10/SUM(Y$16,Y$13,Y$10) -> 1206.2965 | Y10: 783 | Z10: SEO・AIO対策
B11: 目標値 | E11: 目標値 | H11: SQL数/SQL化率 | K11: 目標値 | N11: MQL数/CVR | P11: =P10-N10 -> -1340 | S11: 前年実績セッション数/可変チャネルの前年実績合計セッション数×可変チャネル必要流入数 | T11: 目安値 | U11: 前年実績 | V11: 前年実績 | X11: 前年実績セッション数/可変施策の前年実績合計セッション数×必要セッション数（チャネルごと） | Y11: 前年実績 | Z11: 検索ニーズ起点の記事制作
W12: 事例｜case | X12: 必要セッション数 | Y12: セッション数 | Z12: 業界別事例
E13: 受注率 | H13: SQL化率 | K13: SAL化率 | X13: =(S$10-Y$19)*Y13/SUM(Y$16,Y$13,Y$10) -> 1502.0933 | Y13: 975 | Z13: 検索ニーズ起点のLP制作
E14: =B10/E10 -> 0.33333333 | H14: =E10/H10 -> 0.2173913 | K14: =H10/K10 -> 0.30666667 | X14: 前年実績セッション数/可変施策の前年実績合計セッション数×必要セッション数（チャネルごと） | Y14: 前年実績 | Z14: TOPページ改善
E15: 受注件数/SQL数 | H15: 前年実績 | K15: SAL数/MQL数 | W15: コラム｜column | X15: 必要セッション数 | Y15: セッション数
X16: =(S$10-Y$19)*Y16/SUM(Y$16,Y$13,Y$10) -> 24386.293 | Y16: 15829
X17: 前年実績セッション数/可変施策の前年実績合計セッション数×必要セッション数（チャネルごと） | Y17: 前年実績
W18: その他｜nurse_problem,feature,reasons,news,company,useful,catalog,フォーム,その他 | X18: 必要セッション数 | Y18: セッション数
X19: 1850 | Y19: =19437-SUM(Y10,Y13,Y16) -> 1850
X20: 前年実績 | Y20: 前年実績
W21: FAQページ
W22: 内部リンク | Z22: 回遊導線整備
R23: Paid
N24: CVR | O24: 事例 | R24: =S25/$N$10 -> 0.15884432 | S24: 必要セッション数 | T24: MQL数 | U24: MQL数 | V24: CVR | W24: TOP｜/ | X24: 必要セッション数 | Y24: セッション数 | Z24: TOPページ改善
N25: ='2025年度実績確認'!J36 -> 0.0096086309 | O25: WP追加 | S25: ='2025年度実績確認'!J39 -> 7439.1394 | T25: =(K$10-SUM(U$36,U$40,U$67))*U25/SUM(U$10,U$25,U$44,U$56) -> 109.26259 | U25: 81 | V25: =IF(S25=0,0,U25/S25) -> 0.010888356 | X25: =(S$25-Y$31)*Y25/SUM(Y$25,Y$28) -> 7031.9995 | Y25: 4658 | Z25: クリエイティブ改善
N26: 前年実績 | O26: フォーム最適化 | S26: 前年実績セッション数/可変チャネルの前年実績合計セッション数×可変チャネル必要流入数 | T26: 目安値 | U26: 前年実績 | V26: 前年実績 | X26: 前年実績セッション数/可変施策の前年実績合計セッション数×必要セッション数（チャネルごと） | Y26: 前年実績 | Z26: キーワード拡張
W27: カタログ一覧｜catalog | X27: 必要セッション数 | Y27: セッション数 | Z27: ターゲティング改善
X28: =(S$25-Y$31)*Y28/SUM(Y$25,Y$28) -> 178.13996 | Y28: 118 | Z28: LP制作・改善
X29: 前年実績セッション数/可変施策の前年実績合計セッション数×必要セッション数（チャネルごと） | Y29: 前年実績
W30: その他｜case,column,nurse_problem,feature,reasons,news,company,useful,フォーム,その他 | X30: 必要セッション数 | Y30: セッション数
X31: =Y31 -> 229 | Y31: =5005-SUM(Y25,Y28) -> 229
X32: 前年実績 | Y32: 前年実績
R34: Display
R35: =S36/$N$10 -> 0.035274352 | S35: 必要セッション数 | T35: MQL数 | U35: MQL数 | V35: CVR | W35: ※再訪喚起につながる改善
S36: ='2025年度実績確認'!J40 -> 1652 | T36: =K$10*U36/SUM(U$10,U$25,U$36,U$40,U$44,U$56,U$67) -> 0 | U36: 0 | V36: =IF(S36=0,0,U36/S36) -> 0
S37: 前年実績 | T37: 目安値 | U37: 前年実績 | V37: 前年実績
R38: Direct
R39: =S40/$N$10 -> 0.084897592 | S39: 必要セッション数 | T39: MQL数 | U39: MQL数 | V39: CVR | W39: ※ブランディング（ブランド想起・再訪喚起）
S40: ='2025年度実績確認'!J41 -> 3976 | T40: 33 | U40: 33 | V40: =IF(S40=0,0,U40/S40) -> 0.0082997988 | W40: 【保存版」のようなHowto系コンテンツ
S41: 前年実績 | T41: 目安値 | U41: 前年実績 | V41: 前年実績
R42: Email
...

Sheet IS｜KPIツリー（構造確認用）
A1: KPIツリー（構成イメージ）
A2: サンプル：IS 2025実績&2026目標 | H2: KPIツリー（Miro）
H3: https://miro.com/app/board/uXjVHZpxzbo=/
I4: 目標値
I5: 前年実績
I6: 施策により可変な数値
B8: ※マーケ起点 | R8: Organic | Z8: 施策例
B9: 受注件数 | E9: SQL数 | H9: SAL数 | K9: MQL数 | N9: 必要セッション数 | P9: =SUM(R9,R27,R38,R51,R55,R67) -> 0.98056704 | R9: =S10/$N$10 -> 0.22452059 | S9: 必要セッション数 | T9: MQL数 | U9: MQL数 | V9: CVR | W9: TOP｜/ | X9: 必要セッション数 | Y9: セッション数 | Z9: 掲載本数（ボリューム）
B10: ='2025年度実績確認'!K29 -> 4 | E10: ='2025年度実績確認'!K31 -> 12 | H10: ='2025年度実績確認'!K33 -> 54.857143 | K10: ='2025年度実績確認'!K35 -> 276 | N10: =K10/N28 -> 25163.438 | P10: =SUM(S10,S28,S39,S52,S56,S68) -> 24674.438 | S10: ='2025年度実績確認'!K38 -> 5649.71 | T10: =(K$10-SUM(U$28,U$52,U$79))*U10/SUM(U$10,U$39,U$56,U$68) -> 4.5460123 | U10: 3 | V10: =IF(S10=0,0,U10/S10) -> 0.00053100071 | X10: =(S$10-Y$22)*Y10/SUM(Y$16,Y$13,Y$19,Y$10) -> 1333.5464 | Y10: 651 | Z10: SEO・AIO対策
B11: 目標値 | E11: 目標値 | H11: SQL数/SQL化率 | K11: 目標値 | N11: MQL数/CVR | P11: =P10-N10 -> -489 | S11: 前年実績セッション数/可変チャネルの前年実績合計セッション数×可変チャネル必要流入数 | T11: 目安値 | U11: 前年実績 | V11: 前年実績 | X11: 前年実績セッション数/可変施策の前年実績合計セッション数×必要セッション数（チャネルごと） | Y11: 前年実績 | Z11: 検索ニーズ起点の記事制作
W12: 事例｜case | X12: 必要セッション数 | Y12: セッション数 | Z12: 業界別事例
E13: 受注率 | H13: SQL化率 | K13: SAL化率 | X13: =(S$10-Y$22)*Y13/SUM(Y$16,Y$13,Y$19,Y$10) -> 2062.7976 | Y13: 1007 | Z13: 検索ニーズ起点のLP制作
E14: =B10/E10 -> 0.33333333 | H14: =E10/H10 -> 0.21875 | K14: =H10/K10 -> 0.19875776 | X14: 前年実績セッション数/可変施策の前年実績合計セッション数×必要セッション数（チャネルごと） | Y14: 前年実績 | Z14: TOPページ改善
E15: 受注件数/SQL数 | H15: 前年実績 | K15: SAL数/MQL数 | W15: コラム｜column | X15: 必要セッション数 | Y15: セッション数
X16: =(S$10-Y$22)*Y16/SUM(Y$16,Y$13,Y$19,Y$10) -> 1147.1367 | Y16: 560
X17: 前年実績セッション数/可変施策の前年実績合計セッション数×必要セッション数（チャネルごと） | Y17: 前年実績
W18: LP｜promotion,branding,oem-odm | X18: 必要セッション数 | Y18: セッション数
X19: =(S$10-Y$22)*Y19/SUM(Y$16,Y$13,Y$19,Y$10) -> 559.22915 | Y19: =89+20+164 -> 273
X20: 前年実績セッション数/可変施策の前年実績合計セッション数×必要セッション数（チャネルごと） | Y20: 前年実績
W21: その他｜reason,news,company,whitepaper,フォーム,その他 | X21: 必要セッション数 | Y21: セッション数
X22: =Y22 -> 547 | Y22: =3038-SUM(Y10,Y19,Y13,Y16) -> 547
X23: 前年実績 | Y23: 前年実績
W24: FAQページ
W25: 内部リンク | Z25: 回遊導線整備
R26: Paid
N27: CVR | O27: 事例 | R27: =S28/$N$10 -> 0.045899929 | S27: 必要セッション数 | T27: MQL数 | U27: MQL数 | V27: CVR | W27: TOP｜/ | X27: 必要セッション数 | Y27: セッション数 | Z27: TOPページ改善
N28: ='2025年度実績確認'!K36 -> 0.010968295 | O28: WP追加 | S28: ='2025年度実績確認'!K39 -> 1155 | T28: 0 | U28: 9 | V28: =IF(S28=0,0,U28/S28) -> 0.0077922078 | X28: =(S$28-Y$34)*Y28/SUM(Y$28,Y$31) -> #DIV/0! | Z28: クリエイティブ改善
N29: 前年実績 | O29: フォーム最適化 | S29: 前年実績 | T29: 目安値 | U29: 前年実績 | V29: 前年実績 | X29: 前年実績セッション数/可変施策の前年実績合計セッション数×必要セッション数（チャネルごと） | Y29: 前年実績 | Z29: キーワード拡張
W30: LP｜promotion,branding,oem-odm | X30: 必要セッション数 | Y30: セッション数 | Z30: ターゲティング改善
X31: =(S$28-Y$34)*Y31/SUM(Y$28,Y$31) -> #DIV/0! | Z31: LP制作・改善
X32: 前年実績セッション数/可変施策の前年実績合計セッション数×必要セッション数（チャネルごと） | Y32: 前年実績
W33: その他｜case,column,reason,news,company,whitepaper,フォーム,その他 | X33: 必要セッション数 | Y33: セッション数
X35: 前年実績 | Y35: 前年実績
R37: Display
R38: =S39/$N$10 -> 0.13041318 | S38: 必要セッション数 | T38: MQL数 | U38: MQL数 | V38: CVR | W38: TOP｜/ | X38: 必要セッション数 | Y38: セッション数 | Z38: TOPページ改善
S39: ='2025年度実績確認'!K40 -> 3281.6439 | T39: 9 | U39: 0 | V39: =IF(S39=0,0,U39/S39) -> 0 | X39: =(S$39-Y$48)*Y39/SUM(Y$39,Y$42,Y$45) -> 1273.2984 | Y39: =368+332 -> 700 | Z39: クリエイティブ改善
S40: 前年実績セッション数/可変チャネルの前年実績合計セッション数×可変チャネル必要流入数 | T40: 目安値 | U40: 前年実績 | V40: 前年実績 | X40: 前年実績セッション数/可変施策の前年実績合計セッション数×必要セッション数（チャネルごと） | Y40: 前年実績 | Z40: キーワード拡張
W41: 事例｜case | X41: 必要セッション数 | Y41: セッション数 | Z41: ターゲティング改善
X42: =(S$39-Y$48)*Y42/SUM(Y$39,Y$42,Y$45) -> 1129.5976 | Y42: =336+285 -> 621 | Z42: LP制作・改善
X43: 前年実績セッション数/可変施策の前年実績合計セッション数×必要セッション数（チャネルごと） | Y43: 前年実績
...

Sheet ※作成中※　UN｜KPIツリー（数値管理用）
A1: KPIツリー
D2: 3月 | E2: 4月 | F2: 5月 | G2: 6月 | H2: 7月 | I2: 8月 | J2: 9月 | K2: 10月 | L2: 11月 | M2: 12月 | N2: 1月 | O2: 2月 | P2: 計
B3: 受注件数 | C3: 目標 | D3: =D9*D6 -> 0.66666667 | E3: =E9*E6 -> 0.66666667 | F3: =F9*F6 -> 0.66666667 | G3: =G9*G6 -> 0.66666667 | H3: =H9*H6 -> 0.66666667 | I3: =I9*I6 -> 0.66666667 | J3: =J9*J6 -> 0.66666667 | K3: =K9*K6 -> 0.66666667 | ... O3: =O9*O6 -> 0.66666667 | P3: 8
B4: ※FLUED月次レポートより | C4: 実績 | D4: 0
C5: 差分 | D5: =D4-D3 -> -0.66666667
B6: 受注率 | C6: 目標 | D6: =$P$6 -> 0.13333333 | E6: =$P$6 -> 0.13333333 | F6: =$P$6 -> 0.13333333 | G6: =$P$6 -> 0.13333333 | H6: =$P$6 -> 0.13333333 | I6: =$P$6 -> 0.13333333 | J6: =$P$6 -> 0.13333333 | K6: =$P$6 -> 0.13333333 | ... O6: =$P$6 -> 0.13333333 | P6: =P3/P9 -> 0.13333333
C7: 実績 | D7: =D4/D9 -> 0
C8: 差分(pt)
B9: SQL数 | C9: 目標 | D9: =$P$9/12 -> 5 | E9: =$P$9/12 -> 5 | F9: =$P$9/12 -> 5 | G9: =$P$9/12 -> 5 | H9: =$P$9/12 -> 5 | I9: =$P$9/12 -> 5 | J9: =$P$9/12 -> 5 | K9: =$P$9/12 -> 5 | ... O9: =$P$9/12 -> 5 | P9: 60
B10: ※FLUED月次レポートより | C10: 実績 | D10: 2
C11: 差分 | D11: =D10-D9 -> -3
B12: SQL化率 | C12: 目標 | D12: =$P$12 -> 0.85714286 | E12: =$P$12 -> 0.85714286 | F12: =$P$12 -> 0.85714286 | G12: =$P$12 -> 0.85714286 | H12: =$P$12 -> 0.85714286 | I12: =$P$12 -> 0.85714286 | J12: =$P$12 -> 0.85714286 | K12: =$P$12 -> 0.85714286 | ... O12: =$P$12 -> 0.85714286 | P12: =P9/P15 -> 0.85714286
C13: 実績 | D13: =D10/D16 -> 2
C14: 差分(pt) | D14: =(D13-D12)*100 -> 114.28571
B15: SAL数 | C15: 目標 | D15: =$P$15/12 -> 5.8333333 | E15: =$P$15/12 -> 5.8333333 | F15: =$P$15/12 -> 5.8333333 | G15: =$P$15/12 -> 5.8333333 | H15: =$P$15/12 -> 5.8333333 | I15: =$P$15/12 -> 5.8333333 | J15: =$P$15/12 -> 5.8333333 | K15: =$P$15/12 -> 5.8333333 | ... O15: =$P$15/12 -> 5.8333333 | P15: 70
B16: ※FLUED月次レポートより | C16: 実績 | D16: 1
C17: 差分 | D17: =D16-D15 -> -4.8333333
B18: SAL化率 | C18: 目標 | D18: =$P$18 -> 0.23333333 | E18: =$P$18 -> 0.23333333 | F18: =$P$18 -> 0.23333333 | G18: =$P$18 -> 0.23333333 | H18: =$P$18 -> 0.23333333 | I18: =$P$18 -> 0.23333333 | J18: =$P$18 -> 0.23333333 | K18: =$P$18 -> 0.23333333 | ... O18: =$P$18 -> 0.23333333 | P18: =P15/P21 -> 0.23333333
C19: 実績 | D19: =D16/D22 -> 0.125
C20: 差分(pt) | D20: =(D19-D18)*100 -> -10.833333
B21: MQL数 | C21: 目標 | D21: =D27*D24 -> 25 | E21: =E27*E24 -> 25 | F21: =F27*F24 -> 25 | G21: =G27*G24 -> 25 | H21: =H27*H24 -> 25 | I21: =I27*I24 -> 25 | J21: =J27*J24 -> 25 | K21: =K27*K24 -> 25 | ... O21: =O27*O24 -> 25 | P21: 300
B22: ※FLUED月次レポートより | C22: 実績 | D22: 8
C23: 差分 | D23: =D22-D21 -> -17
B24: CVR（MQL化率） | C24: 目標 | D24: =$P$24 -> 0.0075 | E24: =$P$24 -> 0.0075 | F24: =$P$24 -> 0.0075 | G24: =$P$24 -> 0.0075 | H24: =$P$24 -> 0.0075 | I24: =$P$24 -> 0.0075 | J24: =$P$24 -> 0.0075 | K24: =$P$24 -> 0.0075 | ... O24: =$P$24 -> 0.0075 | P24: =P21/P27 -> 0.0075
C25: 実績 | D25: =D22/D28 -> 0.0026481298
C26: 差分(pt) | D26: =(D25-D24)*100 -> -0.48518702
B27: セッション数 | C27: 目標 | D27: =$P$27/12 -> 3333.3333 | E27: =$P$27/12 -> 3333.3333 | F27: =$P$27/12 -> 3333.3333 | G27: =$P$27/12 -> 3333.3333 | H27: =$P$27/12 -> 3333.3333 | I27: =$P$27/12 -> 3333.3333 | J27: =$P$27/12 -> 3333.3333 | K27: =$P$27/12 -> 3333.3333 | ... O27: =$P$27/12 -> 3333.3333 | P27: 40000
C28: 実績 | D28: 3021 | E28: 3178
C29: 差分 | D29: =D28-D27 -> -312.33333 | E29: =E28-E27 -> -155.33333 | F29: =F28-F27 -> -3333.3333 | G29: =G28-G27 -> -3333.3333 | H29: =H28-H27 -> -3333.3333 | I29: =I28-I27 -> -3333.3333 | J29: =J28-J27 -> -3333.3333 | K29: =K28-K27 -> -3333.3333 | ... O29: =O28-O27 -> -3333.3333
A32: チャネル別
B33: 受注件数
B34: 受注率
B35: SQL数
B36: SQL化率
B37: SAL数
B38: SAL化率
A39: Organic | B39: MQL数
A40: Organic | B40: CVR（MQL化率）
A41: Organic | B41: セッション数 | C41: 目標 | D41: ='UN｜KPIツリー（構造確認用）'!$S$10/12 -> 1559.7511 | E41: ='UN｜KPIツリー（構造確認用）'!$S$10/12 -> 1559.7511 | F41: ='UN｜KPIツリー（構造確認用）'!$S$10/12 -> 1559.7511 | G41: ='UN｜KPIツリー（構造確認用）'!$S$10/12 -> 1559.7511 | H41: ='UN｜KPIツリー（構造確認用）'!$S$10/12 -> 1559.7511 | I41: ='UN｜KPIツリー（構造確認用）'!$S$10/12 -> 1559.7511 | J41: ='UN｜KPIツリー（構造確認用）'!$S$10/12 -> 1559.7511 | K41: ='UN｜KPIツリー（構造確認用）'!$S$10/12 -> 1559.7511 | ... O41: ='UN｜KPIツリー（構造確認用）'!$S$10/12 -> 1559.7511
A42: Organic | B42: セッション数 | C42: 実績
...

Sheet UN | 施策運用表_流入施策
A1: 流入施策
A3: チャネル別流入数 | K3: コラム | ランディングページのセッション数 ※GA4
A4: 月 | B4: セッション数計 | C4: Organic | D4: Paid | E4: Display | F4: Direct | G4: Email | H4: Referral | I4: その他 | K4: 記事名 | L4: URL | M4: スラッグ | N4: 公開月 | O4: 46095 | P4: 46113 | Q4: 46143 | R4: 46174 | S4: 46204 | T4: 46235 | U4: 46266 | V4: 46296 | W4: 46327 | X4: 46357 | Y4: 46388 | Z4: 46419
A5: 46095 | B5: 3021 | C5: 1599 | D5: 484 | F5: 625 | G5: 165 | H5: 125 | I5: =B5-(C5+D5+F5+G5+H5) -> 23 | K5: ユニフォーム導入により期待できる効果・メリットをご紹介 | L5: https://uniform.onward-cd.co.jp/column/original_uniform_effect | M5: original_uniform_effect | O5: 36 | P5: 34
A6: 46113 | B6: 3178 | C6: 1900 | D6: 326 | F6: 580 | G6: 157 | H6: 171 | I6: =B6-(C6+D6+F6+G6+H6) -> 44 | K6: 法人向け作業服をオリジナルデザインで制作する際の流れとは？ | L6: https://uniform.onward-cd.co.jp/column/workuniform_flow | M6: workuniform_flow | O6: 9 | P6: 6
A7: 46143 | I7: =B7-(C7+D7+F7+G7+H7) -> 0 | K7: JIS T 8118とは？3つの規定や着用が必要な現場について解説 | L7: https://uniform.onward-cd.co.jp/column/jis-t-8118/ | M7: jis-t-8118 | O7: 199 | P7: 181
A8: 46174 | I8: =B8-(C8+D8+F8+G8+H8) -> 0 | K8: 【熱中症対策の義務化】 対応に最適な涼しい作業服・快適な作業服にはどんな種類・素材・機能がある？最適な作業服の選び方もご紹介 | L8: https://uniform.onward-cd.co.jp/column/cool_work_clothes/ | M8: cool_work_clothes | O8: 28 | P8: 36
A9: 46204 | I9: =B9-(C9+D9+F9+G9+H9) -> 0 | K9: おしゃれなユニフォームとはどのようなものがある？ ユニフォームにおしゃれを取り入れるためのポイントも解説 | L9: https://uniform.onward-cd.co.jp/column/stylish_uniform/ | M9: stylish_uniform | O9: 13 | P9: 7
A10: 46235 | I10: =B10-(C10+D10+F10+G10+H10) -> 0 | K10: 【目的別】周年行事・周年記念アイデア集 ブランディング効果を高めるポイントも解説 | L10: https://uniform.onward-cd.co.jp/column/anniversary_event_idea/ | M10: anniversary_event_idea | O10: 23 | P10: 23
A11: 46266 | I11: =B11-(C11+D11+F11+G11+H11) -> 0 | K11: アウターブランディングとは？ インナーブランディングとの違いや成功ポイントについても紹介 | L11: https://uniform.onward-cd.co.jp/column/outer_branding/ | M11: outer_branding | O11: 7 | P11: 12
A12: 46296 | I12: =B12-(C12+D12+F12+G12+H12) -> 0 | K12: ブランドカラーとは？ コーポレートカラーとの違いやカラーの使用時の注意点も解説 | L12: https://uniform.onward-cd.co.jp/column/brand_color/ | M12: brand_color | O12: 41 | P12: 59
A13: 46327 | I13: =B13-(C13+D13+F13+G13+H13) -> 0 | K13: 企業イメージを向上させる施策と企業イメージを左右する要因を解説 | L13: https://uniform.onward-cd.co.jp/column/improving_corporate_image/ | M13: improving_corporate_image | O13: 17 | P13: 11
A14: 46357 | I14: =B14-(C14+D14+F14+G14+H14) -> 0 | K14: 【保存版】会社ユニフォームを選定する上で押さえておくべき3つの視点とは？ | L14: https://uniform.onward-cd.co.jp/column/uniform_selection_point/ | M14: uniform_selection_point | O14: 15 | P14: 21
A15: 46388 | I15: =B15-(C15+D15+F15+G15+H15) -> 0 | K15: 受付・接客スタッフ向け｜ブランド価値を体現する「ユニフォームカラー設計」の考え方 | L15: https://uniform.onward-cd.co.jp/column/uniform_color_design/ | M15: uniform_color_design | O15: 3 | P15: 4
A16: 46419 | I16: =B16-(C16+D16+F16+G16+H16) -> 0 | K16: 「小売・外食・宅配ユニフォーム」の正解は？“動ける”接客を支えるユニフォーム選びとは | L16: https://uniform.onward-cd.co.jp/column/comfortable_uniform/ | M16: comfortable_uniform | O16: 1 | P16: 2
K17: 【職種別に紹介】旅客運輸業界のユニフォームに必要な性能・仕様を解説 | L17: https://uniform.onward-cd.co.jp/column/passenger_transport_industry_uniforms/ | M17: passenger_transport_industry_uniforms | O17: 12 | P17: 6
K18: EcoVadis（エコバディス）とは？オンワードコーポレートデザインがEcoVadis取得で目指すもの | L18: https://uniform.onward-cd.co.jp/column/ecovadis_acquisition/ | M18: ecovadis_acquisition | O18: 4 | P18: 10
K19: ユニフォーム刷新で採用が変わる －採用強化・離職率低下につながった事例紹介－ | L19: https://uniform.onward-cd.co.jp/column/uniform-renewal-recruitment-case | M19: uniform-renewal-recruitment-case | O19: 4 | P19: 2
K20: 現場で選ばれる「IEC対応作業服」の実態 電気設備業務における安全基準と発注リスク低減のポイント | L20: https://uniform.onward-cd.co.jp/column/iec-workwear/ | M20: iec-workwear | O20: 30 | P20: 14
K21: 女性が選びたくなる作業着で採用力を強化！レディース作業服のトレンドと導入のポイント | L21: https://uniform.onward-cd.co.jp/column/women-work-clothes/ | M21: women-work-clothes | O21: 16 | P21: 43
K22: 職場の暑熱対策はどう変わる？2025年の熱中症対策義務化で進む、企業ユニフォームの最新トレンド | L22: https://uniform.onward-cd.co.jp/column/heat-measures/ | M22: heat-measures | N22: 46113 | P22: 24
N23: 計 | O23: =SUM(O5:O22) -> 458 | P23: =SUM(P5:P22) -> 495
K25: メルマガ | 流入数 ※HubSpot
K26: 月 | L26: 配信名 | M26: 訴求内容 | N26: 配信数 | O26: 開封数 | P26: 開封率 | Q26: CTAクリック数 | R26: CTAクリック率
K27: 46084 | L27: UN | メルマガNo.16 | M27: 【成功事例紹介】食品販売・外食・宅配のユニフォームリニューアル成功パターン3選 | N27: 4052 | O27: =N27*P27 -> 502.0428 | P27: 0.1239 | Q27: 13 | R27: 0.0032
K28: 46107 | L28: UN | メルマガNo.26 | M28: 【基礎から解説】IEC対応作業服とは？初心者にも分かるポイント整理 | N28: 4033 | O28: =N28*P28 -> 535.1791 | P28: 0.1327 | Q28: 17 | R28: 0.0042
K29: 46111 | L29: UN | 内製メルマガNo.32 | M29: 【無料進呈】ユニフォーム導入で失敗しないための「事前準備チェックシート」 | N29: 4019 | O29: =N29*P29 -> 551.0049 | P29: 0.1371 | Q29: 19 | R29: 0.0047
K30: 46118 | L30: UN | 内製メルマガNo.33 | M30: 【人手不足対策】選ばれる企業になるために。最新女性用作業着のトレンドとは？ | N30: 3987 | O30: =N30*P30 -> 527.8788 | P30: 0.1324 | Q30: 28 | R30: 0.007
K31: 46134 | L31: UN | メルマガNo.31 | M31: ※飲食・接客セグメント配信 | N31: 953 | O31: =N31*P31 -> 125.9866 | P31: 0.1322 | Q31: 10 | R31: 0.0709
O32: =N32*P32 -> 0
O33: =N33*P33 -> 0
O34: =N34*P34 -> 0
O35: =N35*P35 -> 0
O36: =N36*P36 -> 0
O37: =N37*P37 -> 0
O38: =N38*P38 -> 0
O39: =N39*P39 -> 0
O40: =N40*P40 -> 0

Sheet UN｜施策運用表_CVR施策
A1: CVR施策
A3: CV発生数 | G3: 実績・事例 | CTAクリック数 ※GA4
A4: 月 | B4: セッション数計 | C4: CTAクリック数 | D4: CV貢献スコア | E4: 総CV数 | G4: 事例名 | H4: URL | I4: スラッグ | J4: 公開月 | K4: 46095 | L4: 46113 | M4: 46143 | N4: 46174 | O4: 46204 | P4: 46235 | Q4: 46266 | R4: 46296 | S4: 46327 | T4: 46357 | U4: 46388 | V4: 46419
A5: 46095 | E5: =K81 -> 4 | G5: 工場内作業服 | キオクシア株式会社 | H5: https://uniform.onward-cd.co.jp/case/kioxia/ | I5: kioxia
A6: 46113 | E6: =L81 -> 165 | G6: 建設・運送・インフラ作業服 | ヤマト運輸株式会社 | H6: https://uniform.onward-cd.co.jp/case/yamato_transport/ | I6: yamato_transport
A7: 46143 | E7: =M81 -> 0 | G7: 建設・運送・インフラ作業服 | セントラル警備保障株式会社 | H7: https://uniform.onward-cd.co.jp/case/csp/ | I7: csp
A8: 46174 | E8: =N81 -> 0 | G8: 建設・運送・インフラ作業服 | 東鉄工業株式会社 | H8: https://uniform.onward-cd.co.jp/case/totetsu/ | I8: totetsu
A9: 46204 | E9: =O81 -> 0 | G9: 建設・運送・インフラ作業服 | 野村不動産パートナーズ株式会社 | H9: https://uniform.onward-cd.co.jp/case/nomura-pt | I9: nomura-pt
A10: 46235 | E10: =P81 -> 0 | G10: ファッション系ユニフォーム | 株式会社ファンケル | H10: https://uniform.onward-cd.co.jp/case/fancl/ | I10: fancl
A11: 46266 | E11: =Q81 -> 0 | G11: 接客ユニフォーム | 株式会社ヤクルト本社 | H11: https://uniform.onward-cd.co.jp/case/yakult/ | I11: yakult
A12: 46296 | E12: =R81 -> 0 | G12: 接客ユニフォーム | 株式会社JR東海リテイリング・プラス | H12: https://uniform.onward-cd.co.jp/case/jr-plus/ | I12: jr-plus
A13: 46327 | E13: =S81 -> 0 | G13: 建設・運送・インフラ作業服 | 三菱電機ビルソリューションズ株式会社 | H13: https://uniform.onward-cd.co.jp/case/mebs/ | I13: mebs
A14: 46357 | E14: =T81 -> 0 | G14: 接客ユニフォーム | 株式会社ライフコーポレーション | H14: https://uniform.onward-cd.co.jp/case/lifecorp/ | I14: lifecorp
A15: 46388 | E15: =U81 -> 0 | G15: 建設・運送・インフラ作業服 | 株式会社クラシアン | H15: https://uniform.onward-cd.co.jp/case/qracian/ | I15: qracian
A16: 46419 | E16: =V81 -> 0 | G16: 接客ユニフォーム | 株式会社スタジオアリス | H16: https://uniform.onward-cd.co.jp/case/studio-alice/ | I16: studio-alice
G17: 清掃・メンテナンス作業服 | 新幹線メンテナンス東海株式会社 | H17: https://uniform.onward-cd.co.jp/case/smt/ | I17: smt
G18: 外食・販売ユニフォーム | 株式会社新宿高野 | H18: https://uniform.onward-cd.co.jp/case/takano/ | I18: takano
G19: 接客ユニフォーム | 株式会社シーボン | H19: https://uniform.onward-cd.co.jp/case/cbon/ | I19: cbon
G20: 外食・販売ユニフォーム | 株式会社ドトールコーヒー | H20: https://uniform.onward-cd.co.jp/case/doutor/ | I20: doutor
G21: 清掃・メンテナンス作業服 | 関電ファシリティーズ株式会社 | H21: https://uniform.onward-cd.co.jp/case/kanden-fa/ | I21: kanden-fa
G22: 建設・運送・インフラ作業服 | SBSホールディングス株式会社 | H22: https://uniform.onward-cd.co.jp/case/sbs-group/ | I22: sbs-group
G23: 工場内作業服 | コクヨ株式会社 | H23: https://uniform.onward-cd.co.jp/case/kokuyo/ | I23: kokuyo
G24: 接客ユニフォーム | 株式会社ルネサンス | H24: https://uniform.onward-cd.co.jp/case/renaissance/ | I24: renaissance
G25: 清掃・メンテナンス作業服 | 相鉄企業株式会社 | H25: https://uniform.onward-cd.co.jp/case/sotetsu-kigyo/ | I25: sotetsu-kigyo
G26: 建設・運送・インフラ作業服 | 大成建設グループ | H26: https://uniform.onward-cd.co.jp/case/taisei/ | I26: taisei
G27: 外食・販売ユニフォーム | 株式会社ルピシア | H27: https://uniform.onward-cd.co.jp/case/lupicia/ | I27: lupicia
G28: 接客ユニフォーム | TOHOシネマズ株式会社 | H28: https://uniform.onward-cd.co.jp/case/tohocinemas | I28: tohocinemas
... G30: 工場内作業服 | TDK株式会社 | H30: https://uniform.onward-cd.co.jp/case/tdk_interview/ | I30: tdk_interview
J31: 計 | K31: =SUM(K5:K30) -> 0 | L31: =SUM(L5:L30) -> 0
G33: コラム | CTAクリック数 ※GA4
G34: 記事名 | H34: URL | I34: スラッグ | J34: 公開月 | K34: 46095 | L34: 46113 | M34: 46143 | N34: 46174 | O34: 46204 | P34: 46235 | Q34: 46266 | R34: 46296 | S34: 46327 | T34: 46357 | U34: 46388 | V34: 46419
G35: ユニフォーム導入により期待できる効果・メリットをご紹介 | H35: https://uniform.onward-cd.co.jp/column/original_uniform_effect | I35: original_uniform_effect
G36: 法人向け作業服をオリジナルデザインで制作する際の流れとは？ | H36: https://uniform.onward-cd.co.jp/column/workuniform_flow | I36: workuniform_flow
G37: JIS T 8118とは？3つの規定や着用が必要な現場について解説 | H37: https://uniform.onward-cd.co.jp/column/jis-t-8118/ | I37: jis-t-8118
G38: 【熱中症対策の義務化】 対応に最適な涼しい作業服・快適な作業服にはどんな種類・素材・機能がある？最適な作業服の選び方もご紹介 | H38: https://uniform.onward-cd.co.jp/column/cool_work_clothes/ | I38: cool_work_clothes
G39: おしゃれなユニフォームとはどのようなものがある？ ユニフォームにおしゃれを取り入れるためのポイントも解説 | H39: https://uniform.onward-cd.co.jp/column/stylish_uniform/ | I39: stylish_uniform
G40: 【目的別】周年行事・周年記念アイデア集 ブランディング効果を高めるポイントも解説 | H40: https://uniform.onward-cd.co.jp/column/anniversary_event_idea/ | I40: anniversary_event_idea
G41: アウターブランディングとは？ インナーブランディングとの違いや成功ポイントについても紹介 | H41: https://uniform.onward-cd.co.jp/column/outer_branding/ | I41: outer_branding
G42: ブランドカラーとは？ コーポレートカラーとの違いやカラーの使用時の注意点も解説 | H42: https://uniform.onward-cd.co.jp/column/brand_color/ | I42: brand_color
G43: 企業イメージを向上させる施策と企業イメージを左右する要因を解説 | H43: https://uniform.onward-cd.co.jp/column/improving_corporate_image/ | I43: improving_corporate_image
...

Sheet 定義
A1: マーケティングKPIツリー
A3: ■目的
A4: 全体売上に対するマーケ起点売上比率10％を達成するために、必要な受注数・SQL数・MQL数・リード数・流入数を逆算し、施策別に月次管理する
A6: ■シート構成
A7: 定義
A8: KGI設定
A9: 施策別計画
A10: ファネル集計
A11: ダッシュボード
A13: ■入力ルール
A14: 黄色セル：手入力
A15: 灰色セル：数式
... A41: ウェビナー

Sheet KGI設定
A1: KGI設定 | B1: 最上位KGIから、必要受注数・必要SQL数・必要MQL数を逆算する
A3: 年度 | B3: 2026
A4: 売上目標
A5: マーケ起点売上比率目標 | B5: 0.1
A6: マーケ起点売上目標 | B6: =B4*B5 -> 0
A7: 平均受注単価
A8: 必要受注件数 | B8: =IFERROR(B6/B7,0) -> 0
A9: 受注率計画
A10: 必要SQL数 | B10: =IFERROR(B8/B9,0) -> 0
A11: SQL化率計画
A12: 必要SAL数 | B12: =IFERROR(B10/B11,0) -> 0
A13: SAL化率計画
A14: 必要MQL数 | B14: =IFERROR(B12/B13,0) -> 0
A15: MQL化率計画
A16: 必要リード数 | B16: =IFERROR(B14/B15,0) -> 0
A17: 流入→リード率計画
A18: 必要流入数（セッション数） | B18: =IFERROR(B16/B17,0) -> 0

Sheet ファネル計画
A1: ファネル計画
A3: 月 | B3: サイト訪問ユーザー数 | C3: MQL数 | D3: SAL数 | E3: SQL数 | F3: 受注件数 | G3: 売上
A4: 3 | B4: =KGI設定!$B$16/12 -> 0 | C4: =KGI設定!$B$14/12 -> 0 | D4: =KGI設定!$B$12/12 -> 0 | E4: =KGI設定!$B$10/12 -> 0 | F4: =KGI設定!$B$8/12 -> 0 | G4: =KGI設定!$B$6/12 -> 0
A5: 4 | B5: =KGI設定!$B$16/12 -> 0 | C5: =KGI設定!$B$14/12 -> 0 | D5: =KGI設定!$B$12/12 -> 0 | E5: =KGI設定!$B$10/12 -> 0 | F5: =KGI設定!$B$8/12 -> 0 | G5: =KGI設定!$B$6/12 -> 0
A6: 5 | B6: =KGI設定!$B$16/12 -> 0 | C6: =KGI設定!$B$14/12 -> 0 | D6: =KGI設定!$B$12/12 -> 0 | E6: =KGI設定!$B$10/12 -> 0 | F6: =KGI設定!$B$8/12 -> 0 | G6: =KGI設定!$B$6/12 -> 0
A7: 6 | B7: =KGI設定!$B$16/12 -> 0 | C7: =KGI設定!$B$14/12 -> 0 | D7: =KGI設定!$B$12/12 -> 0 | E7: =KGI設定!$B$10/12 -> 0 | F7: =KGI設定!$B$8/12 -> 0 | G7: =KGI設定!$B$6/12 -> 0
A8: 7 | B8: =KGI設定!$B$16/12 -> 0 | C8: =KGI設定!$B$14/12 -> 0 | D8: =KGI設定!$B$12/12 -> 0 | E8: =KGI設定!$B$10/12 -> 0 | F8: =KGI設定!$B$8/12 -> 0 | G8: =KGI設定!$B$6/12 -> 0
A9: 8 | B9: =KGI設定!$B$16/12 -> 0 | C9: =KGI設定!$B$14/12 -> 0 | D9: =KGI設定!$B$12/12 -> 0 | E9: =KGI設定!$B$10/12 -> 0 | F9: =KGI設定!$B$8/12 -> 0 | G9: =KGI設定!$B$6/12 -> 0
A10: 9 | B10: =KGI設定!$B$16/12 -> 0 | C10: =KGI設定!$B$14/12 -> 0 | D10: =KGI設定!$B$12/12 -> 0 | E10: =KGI設定!$B$10/12 -> 0 | F10: =KGI設定!$B$8/12 -> 0 | G10: =KGI設定!$B$6/12 -> 0
A11: 10 | B11: =KGI設定!$B$16/12 -> 0 | C11: =KGI設定!$B$14/12 -> 0 | D11: =KGI設定!$B$12/12 -> 0 | E11: =KGI設定!$B$10/12 -> 0 | F11: =KGI設定!$B$8/12 -> 0 | G11: =KGI設定!$B$6/12 -> 0
A12: 11 | B12: =KGI設定!$B$16/12 -> 0 | C12: =KGI設定!$B$14/12 -> 0 | D12: =KGI設定!$B$12/12 -> 0 | E12: =KGI設定!$B$10/12 -> 0 | F12: =KGI設定!$B$8/12 -> 0 | G12: =KGI設定!$B$6/12 -> 0
A13: 12 | B13: =KGI設定!$B$16/12 -> 0 | C13: =KGI設定!$B$14/12 -> 0 | D13: =KGI設定!$B$12/12 -> 0 | E13: =KGI設定!$B$10/12 -> 0 | F13: =KGI設定!$B$8/12 -> 0 | G13: =KGI設定!$B$6/12 -> 0
A14: 1 | B14: =KGI設定!$B$16/12 -> 0 | C14: =KGI設定!$B$14/12 -> 0 | D14: =KGI設定!$B$12/12 -> 0 | E14: =KGI設定!$B$10/12 -> 0 | F14: =KGI設定!$B$8/12 -> 0 | G14: =KGI設定!$B$6/12 -> 0
A15: 2 | B15: =KGI設定!$B$16/12 -> 0 | C15: =KGI設定!$B$14/12 -> 0 | D15: =KGI設定!$B$12/12 -> 0 | E15: =KGI設定!$B$10/12 -> 0 | F15: =KGI設定!$B$8/12 -> 0 | G15: =KGI設定!$B$6/12 -> 0
A16: 合計 | B16: =SUM(B4:B15) -> 0 | C16: =SUM(C4:C15) -> 0 | D16: =SUM(D4:D15) -> 0 | E16: =SUM(E4:E15) -> 0 | F16: =SUM(F4:F15) -> 0 | G16: =SUM(G4:G15) -> 0

Sheet 施策入力
A1: 施策別計画 | C1: 施策単位で、月別の流入・リード・MQL・SQL・受注・売上見込みを入力/計算する
A3: 年月 | B3: 月 | C3: 施策分類 | D3: 施策名 | E3: 実施本数 | F3: 配信/対象数 | G3: 開封率/参加率 | H3: CTR/CVR | I3: セッション数 | J3: MQL数 | K3: SAL数 | L3: SQL数 | M3: 受注件数 | N3: 売上見込み | O3: 主に効く指標 | P3: 計画/実績 | Q3: 備考
A4: 46113 | B4: 4 | C4: メルマガ | D4: メルマガNo.30 | E4: 1 | N4: =IFERROR(M4*KGI設定!$B$7,0) -> 0

Sheet 施策集計
A1: 施策集計
A3: 月 | B3: セッション数 | C3: MQL数 | D3: SAL数 | E3: SQL数 | F3: 受注件数 | G3: 売上見込み
A4: 3 | B4: =SUMIFS(施策入力!$F:$F,施策入力!$A:$A,$A4) -> 0 | C4: =SUMIFS(施策入力!$J:$J,施策入力!$B:$B,$A4,施策入力!$P:$P,"計画") -> 0 | D4: =SUMIFS(施策入力!$K:$K,施策入力!$B:$B,$A4,施策入力!$P:$P,"計画") -> 0 | E4: =SUMIFS(施策入力!$L:$L,施策入力!$B:$B,$A4,施策入力!$P:$P,"計画") -> 0 | F4: =SUMIFS(施策入力!$M:$M,施策入力!$B:$B,$A4,施策入力!$P:$P,"計画") -> 0 | G4: =SUMIFS(施策入力!$N:$N,施策入力!$B:$B,$A4,施策入力!$P:$P,"計画") -> 0
A5: 4 | B5: =SUMIFS(施策入力!$F:$F,施策入力!$A:$A,$A5) -> 0 | C5: =SUMIFS(施策入力!$J:$J,施策入力!$B:$B,$A5,施策入力!$P:$P,"計画") -> 0 | D5: =SUMIFS(施策入力!$K:$K,施策入力!$B:$B,$A5,施策入力!$P:$P,"計画") -> 0 | E5: =SUMIFS(施策入力!$L:$L,施策入力!$B:$B,$A5,施策入力!$P:$P,"計画") -> 0 | F5: =SUMIFS(施策入力!$M:$M,施策入力!$B:$B,$A5,施策入力!$P:$P,"計画") -> 0 | G5: =SUMIFS(施策入力!$N:$N,施策入力!$B:$B,$A5,施策入力!$P:$P,"計画") -> 0
A6: 5 | B6: =SUMIFS(施策入力!$F:$F,施策入力!$A:$A,$A6) -> 0 | C6: =SUMIFS(施策入力!$J:$J,施策入力!$B:$B,$A6,施策入力!$P:$P,"計画") -> 0 | D6: =SUMIFS(施策入力!$K:$K,施策入力!$B:$B,$A6,施策入力!$P:$P,"計画") -> 0 | E6: =SUMIFS(施策入力!$L:$L,施策入力!$B:$B,$A6,施策入力!$P:$P,"計画") -> 0 | F6: =SUMIFS(施策入力!$M:$M,施策入力!$B:$B,$A6,施策入力!$P:$P,"計画") -> 0 | G6: =SUMIFS(施策入力!$N:$N,施策入力!$B:$B,$A6,施策入力!$P:$P,"計画") -> 0
A7: 6 | B7: =SUMIFS(施策入力!$F:$F,施策入力!$A:$A,$A7) -> 0 | C7: =SUMIFS(施策入力!$J:$J,施策入力!$B:$B,$A7,施策入力!$P:$P,"計画") -> 0 | D7: =SUMIFS(施策入力!$K:$K,施策入力!$B:$B,$A7,施策入力!$P:$P,"計画") -> 0 | E7: =SUMIFS(施策入力!$L:$L,施策入力!$B:$B,$A7,施策入力!$P:$P,"計画") -> 0 | F7: =SUMIFS(施策入力!$M:$M,施策入力!$B:$B,$A7,施策入力!$P:$P,"計画") -> 0 | G7: =SUMIFS(施策入力!$N:$N,施策入力!$B:$B,$A7,施策入力!$P:$P,"計画") -> 0
A8: 7 | B8: =SUMIFS(施策入力!$F:$F,施策入力!$A:$A,$A8) -> 0 | C8: =SUMIFS(施策入力!$J:$J,施策入力!$B:$B,$A8,施策入力!$P:$P,"計画") -> 0 | D8: =SUMIFS(施策入力!$K:$K,施策入力!$B:$B,$A8,施策入力!$P:$P,"計画") -> 0 | E8: =SUMIFS(施策入力!$L:$L,施策入力!$B:$B,$A8,施策入力!$P:$P,"計画") -> 0 | F8: =SUMIFS(施策入力!$M:$M,施策入力!$B:$B,$A8,施策入力!$P:$P,"計画") -> 0 | G8: =SUMIFS(施策入力!$N:$N,施策入力!$B:$B,$A8,施策入力!$P:$P,"計画") -> 0
A9: 8 | B9: =SUMIFS(施策入力!$F:$F,施策入力!$A:$A,$A9) -> 0 | C9: =SUMIFS(施策入力!$J:$J,施策入力!$B:$B,$A9,施策入力!$P:$P,"計画") -> 0 | D9: =SUMIFS(施策入力!$K:$K,施策入力!$B:$B,$A9,施策入力!$P:$P,"計画") -> 0 | E9: =SUMIFS(施策入力!$L:$L,施策入力!$B:$B,$A9,施策入力!$P:$P,"計画") -> 0 | F9: =SUMIFS(施策入力!$M:$M,施策入力!$B:$B,$A9,施策入力!$P:$P,"計画") -> 0 | G9: =SUMIFS(施策入力!$N:$N,施策入力!$B:$B,$A9,施策入力!$P:$P,"計画") -> 0
A10: 9 | B10: =SUMIFS(施策入力!$F:$F,施策入力!$A:$A,$A10) -> 0 | C10: =SUMIFS(施策入力!$J:$J,施策入力!$B:$B,$A10,施策入力!$P:$P,"計画") -> 0 | D10: =SUMIFS(施策入力!$K:$K,施策入力!$B:$B,$A10,施策入力!$P:$P,"計画") -> 0 | E10: =SUMIFS(施策入力!$L:$L,施策入力!$B:$B,$A10,施策入力!$P:$P,"計画") -> 0 | F10: =SUMIFS(施策入力!$M:$M,施策入力!$B:$B,$A10,施策入力!$P:$P,"計画") -> 0 | G10: =SUMIFS(施策入力!$N:$N,施策入力!$B:$B,$A10,施策入力!$P:$P,"計画") -> 0
A11: 10 | B11: =SUMIFS(施策入力!$F:$F,施策入力!$A:$A,$A11) -> 0 | C11: =SUMIFS(施策入力!$J:$J,施策入力!$B:$B,$A11,施策入力!$P:$P,"計画") -> 0 | D11: =SUMIFS(施策入力!$K:$K,施策入力!$B:$B,$A11,施策入力!$P:$P,"計画") -> 0 | E11: =SUMIFS(施策入力!$L:$L,施策入力!$B:$B,$A11,施策入力!$P:$P,"計画") -> 0 | F11: =SUMIFS(施策入力!$M:$M,施策入力!$B:$B,$A11,施策入力!$P:$P,"計画") -> 0 | G11: =SUMIFS(施策入力!$N:$N,施策入力!$B:$B,$A11,施策入力!$P:$P,"計画") -> 0
A12: 11 | B12: =SUMIFS(施策入力!$F:$F,施策入力!$A:$A,$A12) -> 0 | C12: =SUMIFS(施策入力!$J:$J,施策入力!$B:$B,$A12,施策入力!$P:$P,"計画") -> 0 | D12: =SUMIFS(施策入力!$K:$K,施策入力!$B:$B,$A12,施策入力!$P:$P,"計画") -> 0 | E12: =SUMIFS(施策入力!$L:$L,施策入力!$B:$B,$A12,施策入力!$P:$P,"計画") -> 0 | F12: =SUMIFS(施策入力!$M:$M,施策入力!$B:$B,$A12,施策入力!$P:$P,"計画") -> 0 | G12: =SUMIFS(施策入力!$N:$N,施策入力!$B:$B,$A12,施策入力!$P:$P,"計画") -> 0
A13: 12 | B13: =SUMIFS(施策入力!$F:$F,施策入力!$A:$A,$A13) -> 0 | C13: =SUMIFS(施策入力!$J:$J,施策入力!$B:$B,$A13,施策入力!$P:$P,"計画") -> 0 | D13: =SUMIFS(施策入力!$K:$K,施策入力!$B:$B,$A13,施策入力!$P:$P,"計画") -> 0 | E13: =SUMIFS(施策入力!$L:$L,施策入力!$B:$B,$A13,施策入力!$P:$P,"計画") -> 0 | F13: =SUMIFS(施策入力!$M:$M,施策入力!$B:$B,$A13,施策入力!$P:$P,"計画") -> 0 | G13: =SUMIFS(施策入力!$N:$N,施策入力!$B:$B,$A13,施策入力!$P:$P,"計画") -> 0
A14: 1 | B14: =SUMIFS(施策入力!$F:$F,施策入力!$A:$A,$A14) -> 0 | C14: =SUMIFS(施策入力!$J:$J,施策入力!$B:$B,$A14,施策入力!$P:$P,"計画") -> 0 | D14: =SUMIFS(施策入力!$K:$K,施策入力!$B:$B,$A14,施策入力!$P:$P,"計画") -> 0 | E14: =SUMIFS(施策入力!$L:$L,施策入力!$B:$B,$A14,施策入力!$P:$P,"計画") -> 0 | F14: =SUMIFS(施策入力!$M:$M,施策入力!$B:$B,$A14,施策入力!$P:$P,"計画") -> 0 | G14: =SUMIFS(施策入力!$N:$N,施策入力!$B:$B,$A14,施策入力!$P:$P,"計画") -> 0
A15: 2 | B15: =SUMIFS(施策入力!$F:$F,施策入力!$A:$A,$A15) -> 0 | C15: =SUMIFS(施策入力!$J:$J,施策入力!$B:$B,$A15,施策入力!$P:$P,"計画") -> 0 | D15: =SUMIFS(施策入力!$K:$K,施策入力!$B:$B,$A15,施策入力!$P:$P,"計画") -> 0 | E15: =SUMIFS(施策入力!$L:$L,施策入力!$B:$B,$A15,施策入力!$P:$P,"計画") -> 0 | F15: =SUMIFS(施策入力!$M:$M,施策入力!$B:$B,$A15,施策入力!$P:$P,"計画") -> 0 | G15: =SUMIFS(施策入力!$N:$N,施策入力!$B:$B,$A15,施策入力!$P:$P,"計画") -> 0
A16: 合計 | B16: =SUM(B4:B15) -> 0 | C16: =SUM(C4:C15) -> 0 | D16: =SUM(D4:D15) -> 0 | E16: =SUM(E4:E15) -> 0 | F16: =SUM(F4:F15) -> 0 | G16: =SUM(G4:G15) -> 0

Sheet ダッシュボード
A1: ダッシュボード
A3: 売上目標 | B3: =KGI設定!B6 -> 0 | C3: 必要MQL数 | D3: =KGI設定!B14 -> 0 | E3: 必要SQL数 | F3: =KGI設定!B10 -> 0
A4: 売上見込み | B4: =施策集計!G16 -> 0 | C4: 見込みMQL数 | D4: =施策集計!C16 -> 0 | E4: 見込みSQL数 | F4: =施策集計!E16 -> 0
A5: 売上差分 | B5: =B4-B3 -> 0 | C5: MQL差分 | D5: =D4-D3 -> 0 | E5: SQL差分 | F5: =F4-F3 -> 0
A8: 月 | B8: セッション数目標 | C8: セッション数見込み | D8: MQL目標 | E8: MQL見込み | F8: SQL目標 | G8: SQL見込み
A9: 3 | B9: =ファネル計画!B4 -> 0 | C9: =施策集計!B4 -> 0 | D9: =ファネル計画!C4 -> 0 | E9: =施策集計!C4 -> 0 | F9: =ファネル計画!E4 -> 0 | G9: =施策集計!E4 -> 0
A10: 4 | B10: =ファネル計画!B5 -> 0 | C10: =施策集計!B5 -> 0 | D10: =ファネル計画!C5 -> 0 | E10: =施策集計!C5 -> 0 | F10: =ファネル計画!E5 -> 0 | G10: =施策集計!E5 -> 0
A11: 5 | B11: =ファネル計画!B6 -> 0 | C11: =施策集計!B6 -> 0 | D11: =ファネル計画!C6 -> 0 | E11: =施策集計!C6 -> 0 | F11: =ファネル計画!E6 -> 0 | G11: =施策集計!E6 -> 0
A12: 6 | B12: =ファネル計画!B7 -> 0 | C12: =施策集計!B7 -> 0 | D12: =ファネル計画!C7 -> 0 | E12: =施策集計!C7 -> 0 | F12: =ファネル計画!E7 -> 0 | G12: =施策集計!E7 -> 0
A13: 7 | B13: =ファネル計画!B8 -> 0 | C13: =施策集計!B8 -> 0 | D13: =ファネル計画!C8 -> 0 | E13: =施策集計!C8 -> 0 | F13: =ファネル計画!E8 -> 0 | G13: =施策集計!E8 -> 0
A14: 8 | B14: =ファネル計画!B9 -> 0 | C14: =施策集計!B9 -> 0 | D14: =ファネル計画!C9 -> 0 | E14: =施策集計!C9 -> 0 | F14: =ファネル計画!E9 -> 0 | G14: =施策集計!E9 -> 0
A15: 9 | B15: =ファネル計画!B10 -> 0 | C15: =施策集計!B10 -> 0 | D15: =ファネル計画!C10 -> 0 | E15: =施策集計!C10 -> 0 | F15: =ファネル計画!E10 -> 0 | G15: =施策集計!E10 -> 0
A16: 10 | B16: =ファネル計画!B11 -> 0 | C16: =施策集計!B11 -> 0 | D16: =ファネル計画!C11 -> 0 | E16: =施策集計!C11 -> 0 | F16: =ファネル計画!E11 -> 0 | G16: =施策集計!E11 -> 0
A17: 11 | B17: =ファネル計画!B12 -> 0 | C17: =施策集計!B12 -> 0 | D17: =ファネル計画!C12 -> 0 | E17: =施策集計!C12 -> 0 | F17: =ファネル計画!E12 -> 0 | G17: =施策集計!E12 -> 0
A18: 12 | B18: =ファネル計画!B13 -> 0 | C18: =施策集計!B13 -> 0 | D18: =ファネル計画!C13 -> 0 | E18: =施策集計!C13 -> 0 | F18: =ファネル計画!E13 -> 0 | G18: =施策集計!E13 -> 0
A19: 1 | B19: =ファネル計画!B14 -> 0 | C19: =施策集計!B14 -> 0 | D19: =ファネル計画!C14 -> 0 | E19: =施策集計!C14 -> 0 | F19: =ファネル計画!E14 -> 0 | G19: =施策集計!E14 -> 0
A20: 2 | B20: =ファネル計画!B15 -> 0 | C20: =施策集計!B15 -> 0 | D20: =ファネル計画!C15 -> 0 | E20: =施策集計!C15 -> 0 | F20: =ファネル計画!E15 -> 0 | G20: =施策集計!E15 -> 0

Sheet Sheet1
A1: セグメント | B1: キーイベント無発生ユーザー | C1: キーイベント発生ユーザー
A2: ページパスとスクリーン クラス | B2: 表示回数 | C2: 表示回数 | D2: RANK（非CV） | E2: RANK（CV） | F2: 非CVとCVの差分
A3: /case/kanden-fa/ | B3: 11 | C3: 1 | D3: =RANK(B3,$B$3:$B$99,0) -> 79 | E3: =RANK(C3,$C$3:$C$99,0) -> 9 | F3: =D3/E3 -> 8.7777778
A4: /contact_c | B4: 104 | C4: 10 | D4: =RANK(B4,$B$3:$B$99,0) -> 17 | E4: =RANK(C4,$C$3:$C$99,0) -> 2 | F4: =D4/E4 -> 8.5
A5: /case/kokuyo/ | B5: 26 | C5: 1 | D5: =RANK(B5,$B$3:$B$99,0) -> 55 | E5: =RANK(C5,$C$3:$C$99,0) -> 9 | F5: =D5/E5 -> 6.1111111
A6: /contact/thanks/ | B6: 32 | C6: 1 | D6: =RANK(B6,$B$3:$B$99,0) -> 51 | E6: =RANK(C6,$C$3:$C$99,0) -> 9 | F6: =D6/E6 -> 5.6666667
A7: /uniform_introduction_guide | B7: 57 | C7: 2 | D7: =RANK(B7,$B$3:$B$99,0) -> 29 | E7: =RANK(C7,$C$3:$C$99,0) -> 6 | F7: =D7/E7 -> 4.8333333
A8: /251205 | B8: 1 | C8: 0 | D8: =RANK(B8,$B$3:$B$99,0) -> 92 | E8: =RANK(C8,$C$3:$C$99,0) -> 20 | F8: =D8/E8 -> 4.6
A9: /colmun/catogory/ | B9: 1 | C9: 0 | D9: =RANK(B9,$B$3:$B$99,0) -> 92 | E9: =RANK(C9,$C$3:$C$99,0) -> 20 | F9: =D9/E9 -> 4.6
A10: /column/test20/ | B10: 1 | C10: 0 | D10: =RANK(B10,$B$3:$B$99,0) -> 92 | E10: =RANK(C10,$C$3:$C$99,0) -> 20 | F10: =D10/E10 -> 4.6
A11: /news/260317/ | B11: 1 | C11: 0 | D11: =RANK(B11,$B$3:$B$99,0) -> 92 | E11: =RANK(C11,$C$3:$C$99,0) -> 20 | F11: =D11/E11 -> 4.6
A12: /news/260326/ | B12: 1 | C12: 0 | D12: =RANK(B12,$B$3:$B$99,0) -> 92 | E12: =RANK(C12,$C$3:$C$99,0) -> 20 | F12: =D12/E12 -> 4.6
A13: /uniform/case/yakult/ | B13: 1 | C13: 0 | D13: =RANK(B13,$B$3:$B$99,0) -> 92 | E13: =RANK(C13,$C$3:$C$99,0) -> 20 | F13: =D13/E13 -> 4.6
A14: /colmun/ | B14: 2 | C14: 0 | D14: =RANK(B14,$B$3:$B$99,0) -> 88 | E14: =RANK(C14,$C$3:$C$99,0) -> 20 | F14: =D14/E14 -> 4.4
... A86: /case/qracian/ | B86: 78 | C86: 0 | D86: =RANK(B86,$B$3:$B$99,0) -> 22 | E86: =RANK(C86,$C$3:$C$99,0) -> 20 | F86: =D86/E86 -> 1.1
B87: 7055 | C87: 43 | D87: =RANK(B87,$B$3:$B$99,0) -> 1 | E87: =RANK(C87,$C$3:$C$99,0) -> 1 | F87: =D87/E87 -> 1
A88: /case/page/4/ | B88: 185 | C88: 1 | D88: =RANK(B88,$B$3:$B$99,0) -> 9 | E88: =RANK(C88,$C$3:$C$99,0) -> 9 | F88: =D88/E88 -> 1
A89: /company/ | B89: 83 | C89: 0 | D89: =RANK(B89,$B$3:$B$99,0) -> 20 | E89: =RANK(C89,$C$3:$C$99,0) -> 20 | F89: =D89/E89 -> 1
A90: /case/kioxia/ | B90: 90 | C90: 0 | D90: =RANK(B90,$B$3:$B$99,0) -> 18 | E90: =RANK(C90,$C$3:$C$99,0) -> 20 | F90: =D90/E90 -> 0.9
A91: /case/page/3/ | B91: 198 | C91: 1 | D91: =RANK(B91,$B$3:$B$99,0) -> 8 | E91: =RANK(C91,$C$3:$C$99,0) -> 9 | F91: =D91/E91 -> 0.88888889
A92: /work/ | B92: 412 | C92: 5 | D92: =RANK(B92,$B$3:$B$99,0) -> 3 | E92: =RANK(C92,$C$3:$C$99,0) -> 4 | F92: =D92/E92 -> 0.75
A93: /case/lifecorp/ | B93: 153 | C93: 0 | D93: =RANK(B93,$B$3:$B$99,0) -> 14 | E93: =RANK(C93,$C$3:$C$99,0) -> 20 | F93: =D93/E93 -> 0.7
A94: / | B94: 1609 | C94: 8 | D94: =RANK(B94,$B$3:$B$99,0) -> 2 | E94: =RANK(C94,$C$3:$C$99,0) -> 3 | F94: =D94/E94 -> 0.66666667
A95: /case/tohocinemas | B95: 167 | C95: 0 | D95: =RANK(B95,$B$3:$B$99,0) -> 13 | E95: =RANK(C95,$C$3:$C$99,0) -> 20 | F95: =D95/E95 -> 0.65
A96: /case/page/2/ | B96: 227 | C96: 1 | D96: =RANK(B96,$B$3:$B$99,0) -> 5 | E96: =RANK(C96,$C$3:$C$99,0) -> 9 | F96: =D96/E96 -> 0.55555556
A97: /case/yamato_transport/ | B97: 185 | C97: 0 | D97: =RANK(B97,$B$3:$B$99,0) -> 9 | E97: =RANK(C97,$C$3:$C$99,0) -> 20 | F97: =D97/E97 -> 0.45
A98: /case/ | B98: 395 | C98: 1 | D98: =RANK(B98,$B$3:$B$99,0) -> 4 | E98: =RANK(C98,$C$3:$C$99,0) -> 9 | F98: =D98/E98 -> 0.44444444
A99: /column/jis-t-8118/ | B99: 223 | C99: 0 | D99: =RANK(B99,$B$3:$B$99,0) -> 6 | E99: =RANK(C99,$C$3:$C$99,0) -> 20 | F99: =D99/E99 -> 0.3

Sheet UN｜月次定例レポート用｜施策と実績
B2: 2025年 | L2: 2026年
B3: 3月 | C3: 4月 | D3: 5月 | E3: 6月 | F3: 7月 | G3: 8月 | H3: 9月 | I3: 10月 | J3: 11月 | K3: 12月 | L3: 1月 | M3: 2月 | N3: 3月 | O3: 4月 | P3: 5月 | Q3: 6月
A4: セッション数 | B4: 2488 | C4: 1957 | D4: 2151 | E4: 2555 | F4: 5132 | G4: 2621 | H4: 2793 | I4: 3227 | J4: 2861 | K4: 2952 | L4: 3381 | M4: 2967 | N4: 3047 | O4: 3156 | P4: 2639
A5: セッション数｜施策種別｜テーマ | E5: ・コラム：No.5 おしゃれなUNとは ・コラム：No.9 企業イメージ向上 | F5: ・コラム：No.10 UN選定3つの視点 ・コラム：No.4Re 熱中症対策義務化 ・お知らせ：TV放映告知 | G5: ・お知らせ：夏季休業 | I5: ・お知らせ：フジテック グッドデザイン賞受賞 | J5: ・お知らせ：・事例 スタジオアリス ・お知らせ：・事例 新幹線メンテナンス東海 ・お知らせ：・事例 新宿高野 ・お知らせ：・事例 関電ファシリティーズ ・お知らせ：・事例 SBSホールディングス ・お知らせ：・事例 コクヨ株式会社 ・お知らせ：冬季休業 | K5: ・お知らせ：・事例 ドトールコーヒー ・お知らせ：・事例 大成建設グループ | L5: ・コラム：No.11UNカラー設計 ・コラム：No.12 小売・外食・宅配UN ・コラム：No.14 EcoVadis ・お知らせ：・事例 ルピシア ・お知らせ：・事例 相鉄企業 ・お知らせ：・事例 TOHOシネマズ ・お知らせ：コラムNo.11 ・お知らせ：コラムNo.12 ・お知らせ：コラムNo.14 | M5: ・コラム：No.3Re JIS T 8118 ・コラム：No.6Re 周年行事・周年記念 ・お知らせ：パタンナーTV放映告知 ・お知らせ：読売新聞掲載・お知らせ ・お知らせ：・事例 フジテック ・お知らせ：コラムNo.3Re ・お知らせ：コラムNo.6Re | N5: ・コラム：No.13 旅客運輸業界UN ・コラム：No.15 採用強化・離職率低下・事例 ・コラム：No.16 IEC対策作業服 ・コラム：No.17 女性が選びたくなる作業着 ・お知らせ：コラムNo.13 ・お知らせ：コラムNo.15 ・お知らせ：コラムNo.16 ・お知らせ：コラムNo.17 ・お知らせ：・事例 TDK | O5: ・コラム：No.18 暑熱対策 ・お知らせ：コラムNo.18 | P5: ・原稿ガイドライン策定 | Q5: ・コラム：No.19人的資本開示 ・コラム：No.20採用難と離職を食い止める ・お知らせ：コラムNo.19 ・お知らせ：コラムNo.20 ・お知らせ：事例NTT東日本
A6: MQL数 | C6: 20 | D6: 13 | E6: 15 | F6: 44 | G6: 29 | H6: 30 | I6: 19 | J6: 23 | K6: 14 | L6: 13 | M6: 13 | N6: 8 | O6: 7 | P6: 44
A7: MQL率 | B7: =B6/B1 -> #DIV/0! | C7: =C6/C4 -> 0.010219724 | D7: =D6/D4 -> 0.0060437006 | E7: =E6/E4 -> 0.0058708415 | F7: =F6/F4 -> 0.0085736555 | G7: =G6/G4 -> 0.011064479 | H7: =H6/H4 -> 0.010741139 | I7: =I6/I4 -> 0.0058878215 | J7: =J6/J4 -> 0.0080391472 | ... Q7: =Q6/Q4 -> #DIV/0!
A8: CV数｜施策種別｜テーマ | C8: ・事例：ヤクルト本社 ・広告：リスティング 微調整 | D8: ・事例：JR東海リテイリング・プラス ・事例：三菱電機ビルソリューションズ ・メルマガ：No.11 コンセプト開発のステップ | E8: ・事例：ライフコーポレーション ・メルマガ：No.10 業種別UN導入ポイント ・広告：リスティング ・広告グループ戦略見直し ・サイト改善：EFO | F8: ・事例：クラシアン ・WP：02 ユニフォーム導入の事前準備チェックシート ・メルマガ：No.18 TV放映（事前） ・メルマガ：No.19 TV放映（当日） ・メルマガ：No.20 TV放映（事後） ・メルマガ：No.12 オリジナルVS既製品 ・メルマガ：No.13 UN選定チェックシート付 ・メルマガ：No.14 熱中症対策義務化 | G8: ・広告：リスティング 一部KW停止 | H8: ・広告：リスティング 一部KW停止 ・広告：リスティング KW追加 ・広告：リスティング KW追加 ・広告：リスティング 職種掛け合わせKW追加 ・広告：リスティング ・広告文見直し・追加 | I8: ・事例：スタジオアリス ・事例：新幹線メンテナンス東海株式会社 ・事例：新宿高野 | J8: ・事例：シーボン ・事例：ドトールコーヒー ・事例：関電ファシリティーズ ・事例：SBSホールディングス ・事例：コクヨ ・広告：リスティング データ除外 ・広告：リスティング リンク表示オプション | K8: ・事例：ルネサンス ・事例：ルピシア ・事例：相鉄企業 ・メルマガ：No.23 カンブリア宮殿再放送告知 ・メルマガ：No.24 2025・コラム紹介 | L8: ・事例：TOHOシネマズ ・メルマガ：No.21 ESG サステナブル素材 ・メルマガ：No.25 2025・事例紹介 | M8: ・事例：フジテック ・サイト改善：画像差し替え・微調整 ・メルマガ：No.22 採用強化・離職率低下 ・メルマガ：No.4Re 周年行事 ・メルマガ：No.5Re UN導入流れ ・メルマガ：No.27 パタンナーTV放映告知（当日） ・メルマガ：No.28 パタンナーTV放映告知（後日） ・メルマガ：No.29 読売新聞記事掲載・お知らせ | N8: ・事例：TDK ・メルマガ：No.16 ・事例紹介 食品販売・外食・宅配 ・メルマガ：No.26 IEC対応作業服 ・メルマガ：No.32 ・WP02紹介 | O8: ・メルマガ：No.31 飲食接客向け・離職率 ・メルマガ：No.33 ・コラム公開・お知らせ（No.17 女性が選びたくなる作業着） ・広告：AIMAX適用開始 | P8: ・WP：03 ボリューム版 ブランド価値を高める制服デザイン戦略 ・メルマガ：No.15 WP03紹介 ・メルマガ：No.30 暑熱対策 | Q8: ・事例：NTT東日本 ・メルマガ：No.34人的資本開示 ・メルマガ：No.35労働災害の防止 ・広告：AIMAXからリスティングに変更 ・広告： DSP広告周年エンタープライズ

Sheet SCH｜月次定例レポート用｜施策と実績
B2: 2025年 | L2: 2026年
B3: 3月 | C3: 4月 | D3: 5月 | E3: 6月 | F3: 7月 | G3: 8月 | H3: 9月 | I3: 10月 | J3: 11月 | K3: 12月 | L3: 1月 | M3: 2月 | N3: 3月 | O3: 4月 | P3: 5月 | Q3: 6月
A4: セッション数 | C4: 1793 | D4: 1571 | E4: 1823 | F4: 1907 | G4: 1415 | H4: 1475 | I4: 1819 | J4: 2088 | K4: 2637 | L4: 2227 | M4: 3811 | N4: 2465 | O4: 2750 | P4: 2887
A5: セッション数｜施策種別｜テーマ | F5: ・コラム：No.7 教員の働き方改革 ・コラム：No.8 チーム学校 ・お知らせ：TV放映告知 | H5: ・お知らせ：展示会 | I5: ・お知らせ：夏季休業 ・お知らせ：Web展示会 ・お知らせ：大阪展示会 | J5: ・お知らせ：展示会後挨拶 ・広告：DSP出稿開始 ・お知らせ：冬季休業 | K5: ・お知らせ：・事例 中大杉並 | L5: ・コラム：No.1Re 制服変更の効果・メリット ・コラム：No.9 制服デザイン ・コラム：No.10 EcoVadis ・お知らせ：コラムNo.1Re ・お知らせ：コラムNo.9 ・お知らせ：コラムNo.10 | M5: ・コラム：No.6Re 学校広報 ・コラム：No.12 LGBTQ・多様性対応 ・広告：DSPバナー差し替え ・お知らせ：TV放映告知 ・お知らせ：コラムNo.6Re ・お知らせ：コラムNo.12 | N5: ・コラム：No.11 制服刷新で変わる志願者数 ・コラム：No.13 学校広報と制服刷新 ・コラム：No.14 学校の暑熱対策 ・お知らせ：コラムNo.13 ・お知らせ：コラムNo.14 ・お知らせ：コラムNo.11 | P5: ・コラム：No.15 制服リニューアル周期 ・コラム：No.16 制服リニューアル検討 ・お知らせ：コラムNo.16 ・広告：DSPバナー停止 ・お知らせ：コラムNo.15
A6: MQL数 | C6: 4 | D6: 5 | E6: 7 | F6: 0 | G6: 2 | H6: 3 | I6: 1 | J6: 2 | K6: 2 | L6: 2 | M6: 3 | N6: 7 | O6: 3 | P6: 4
A7: MQL率 | B7: =B6/B1 -> #DIV/0! | C7: =C6/C4 -> 0.0022308979 | D7: =D6/D4 -> 0.0031826862 | E7: =E6/E4 -> 0.0038398245 | F7: =F6/F4 -> 0 | G7: =G6/G4 -> 0.0014134276 | H7: =H6/H4 -> 0.0020338983 | I7: =I6/I4 -> 0.00054975261 | J7: =J6/J4 -> 0.00095785441 | ... Q7: =Q6/Q4 -> #DIV/0!
A8: CV数｜施策種別｜テーマ | B8: ・メルマガ：プリヘッダー導入 ・広告：リスティング 除外KW追加 ・広告：リスティング KW停止 ・広告：リスティング KW再開 | C8: ・広告：リスティング KW追加 ・広告：リスティング KW停止 | D8: ・広告：リスティング クエリ分析 ・広告：リスティング 上限CPC設定 | E8: ・メルマガ：No.8 学校ブランディング（制服は強力なメディア） ・広告：リスティング キャンペーン複製 ・広告：リスティング ・広告文見直し | F8: ・メルマガ：No.10 制服デザインTips ・メルマガ：No.11 TV放映告知（事前） ・メルマガ：No.12 TV放映告知（当日） ・メルマガ：No.14 EcoVadis | G8: ・メルマガ：No.9 学校のブランド整理 ・広告：リスティング 入札戦略変更 | H8: ・メルマガ：No.3Re 最新制服事情 ・メルマガ：No.15 Web展示会申込 ・LP：Web展示会 | I8: ・メルマガ：No.8Re 制服変更による効果 | J8: ・広告：リスティング データ除外 ・広告：リスティング 入札戦略変更 | K8: ・メルマガ：No.16 制服刷新で変わる志願者数 ・メルマガ：No.17 LGBTQ・多様性対応 ・メルマガ：No.18 カンブリア宮殿再放送 ・事例：中大杉並高校 ・メルマガ：No.19 動画公開・お知らせ ・メルマガ：No.20 2025・コラム紹介 ・メルマガ：No.21 2025・事例紹介 | M8: ・メルマガ：No.23 TV放映告知（当日） ・メルマガ：No.24 TV放映告知（後日） | N8: ・メルマガ：No.22 学校ブランディング ・メルマガ：No.25 暑熱対策・コラム紹介 | O8: ・メルマガ：No.26 制服変更・コラム紹介 | P8: ・メルマガ：No.29 制服見直し ・メルマガ：No.30 制服リニューアル準備 ・事例：筑波大学附属坂戸 | Q8: ・メルマガ：No.27学校広報にも影響 ・メルマガ： No.28制服リニューアルを検討するとき

Sheet MED｜月次定例レポート用｜施策と実績
B2: 2025年 | L2: 2026年
B3: 3月 | C3: 4月 | D3: 5月 | E3: 6月 | F3: 7月 | G3: 8月 | H3: 9月 | I3: 10月 | J3: 11月 | K3: 12月 | L3: 1月 | M3: 2月 | N3: 3月 | O3: 4月 | P3: 5月 | Q3: 6月
A4: セッション数 | C4: 2764 | D4: 3250 | E4: 3298 | F4: 3286 | G4: 2471 | H4: 3002 | I4: 3183 | J4: 2833 | K4: 3119 | L4: 2764 | M4: 3472 | N4: 2188 | O4: 2398 | P4: 2453
A5: セッション数｜施策種別｜テーマ | C5: ・コラム：No.19 SDGs ・コラム：No.20 看護師の業務改善 ・お知らせ：コラムNo.19 ・お知らせ：コラムNo.20 | F5: ・お知らせ：TV放映 | G5: ・お知らせ：夏季休業 | H5: ・コラム：No.16Re トレンドカラー ・コラム：No.3Re ・事例・残業時間・職場づくり | J5: ・お知らせ：冬季休業 | K5: ・コラム：No.1Re 離職率が高い理由 ・コラム：No.14Re 白衣の種類・選び方 ・お知らせ：コラムNo.14Re ・お知らせ：コラムNo.22 ・お知らせ：コラムNo.1Re ・お知らせ：コラムNo.14Re ※重複 | L5: ・コラム：No.21 EcoVadis ・お知らせ：コラムNo.21 | M5: ・お知らせ：パタンナーTV放映告知 ・お知らせ：・事例 同愛記念病院 | N5: ・コラム：No.24 医療現場のユニフォーム改革白書 ・コラム：No.25 医療現場の不便を解決 ・コラム：No.26 涼しいスクラブ ・お知らせ：コラムNo.24 ・お知らせ：コラムNo.25 ・お知らせ：コラムNo.26 | O5: ・コラム：No.27 病院の離職率 ・お知らせ：コラムNo.27 | P5: ・コラム：No.28 看護師の業務フローから見る現場効率化 ・お知らせ：コラムNo.28 ・サイト改修：微修正 | Q5: ・コラム：No.29Raffiriaお薦め商品紹介 ・お知らせ：コラムNo.29
A6: CV-WPDL（実数） | C6: 1 | D6: 1 | E6: 1 | F6: 2 | G6: 0 | H6: 1 | I6: 0 | J6: 0 | K6: 0 | L6: 6 | M6: 21 | N6: 0 | O6: 2
A7: CV-カタログDL（実数） | C7: 20 | D7: 29 | E7: 16 | F7: 45 | G7: 21 | H7: 26 | I7: 29 | J7: 7 | K7: 18 | L7: 30 | M7: 27 | N7: 9 | O7: 25 | Q7: =Q6/Q4 -> #DIV/0!
A8: CV-問い合わせ（実数） | C8: 5 | D8: 3 | E8: 1 | F8: 3 | G8: 1 | H8: 3 | I8: 3 | J8: 1 | K8: 0 | L8: 8 | M8: 4 | N8: 4 | O8: 4
A9: MQL数 | C9: 26 | D9: 27 | E9: 18 | F9: 45 | G9: =SUM(G6:G8) -> 22 | H9: =SUM(H6:H8) -> 30 | I9: =SUM(I6:I8) -> 32 | J9: =SUM(J6:J8) -> 8 | K9: =SUM(K6:K8) -> 18 | L9: =SUM(L6:L8) -> 44 | M9: =SUM(M6:M8) -> 52 | N9: =SUM(N6:N8) -> 13 | O9: 18 | P9: 36
A10: MQL率 | C10: =C9/C4 -> 0.009406657 | D10: =D9/D4 -> 0.0083076923 | E10: =E9/E4 -> 0.0054578532 | F10: =F9/F4 -> 0.013694461 | G10: =G9/G4 -> 0.008903278 | H10: =H9/H4 -> 0.0099933378 | I10: =I9/I4 -> 0.010053409 | J10: =J9/J4 -> 0.0028238616 | ... Q10: =Q9/Q4 -> #DIV/0!
A11: CV数｜施策種別｜テーマ | C11: ・メルマガ改善・リンク設置 ・広告：リスティングKW追加 | D11: ・メルマガ：No.24 速乾白衣紹介 ・メルマガ：No.25 スクラブ透け・色落ち対策 | E11: ・広告：リスティングクエリ追加 | F11: ・メルマガ：No.26 人気スクラブTOP3 ・メルマガ：No.27 TV放映告知 ・メルマガ：No.28 TV放映（当日） ・メルマガ：No.29 TV放映（後日） | G11: ・広告：リスティング一部KW停止 | H11: ・メルマガ：No.30 エコ素材×高機能 ・メルマガ：No.32 看護学会展示告知 | I11: ・メルマガ：No.13Re オリジナル白衣導入メリット ・メルマガ：No.14Re ・事例紹介 山口大医付属・栃木がんセンター ・メルマガ：No.33 展示会フォロー① ・メルマガ：No.34 展示会フォロー② ・メルマガ：No.35 展示会フォロー③ | K11: ・サイト改善：デザイン微調整 ・メルマガ：No.36 冬キャンペーン | L11: ・メルマガ：2025・コラム紹介 ・メルマガ：2025・事例紹介 ・メルマガ：No.31 経営者向け 選ばれる職場の秘訣 ・メルマガ：No.39 ユニフォーム刷新が生んだ5つの変化 | M11: ・メルマガ：No.37 ユニフォーム導入ガイド ・メルマガ：No.38 ユニフォーム改革白書 ・事例：同愛記念病院 ・メルマガ：No.45 パタンナーTV放映告知（当日） ・メルマガ：No.46 パタンナーTV放映告知（後日） ・広告：除外KW追加（指名） ・広告：クエリ一致方法変更 ・広告：リスティングクエリ追加 | N11: ・メルマガ：No.49 医療現場のユニフォーム改革白書 ・メルマガ：No.50 ブランディング動画紹介 | O11: ・メルマガ：No.43 動きやすさ・ユニフォーム設計 ・メルマガ：No.47 病院の離職率 ・広告：指名 検索クエリ追加 ・広告：AIMAXキャンペーン開始 | P11: ・メルマガ：No.48 看護師の業務フローから見る現場効率化（コラムNo.28紹介） ・メルマガ：No.51 病院の価値を高めるメディカルウェア選び方 | Q11: ・メルマガ：No.52 看護師の服装、「色」による違い ・メルマガ：No.53 26年度版Raffiria人気ランキング

Sheet IS｜月次定例レポート用｜施策と実績
B2: 2025年 | L2: 2026年
B3: 3月 | C3: 4月 | D3: 5月 | E3: 6月 | F3: 7月 | G3: 8月 | H3: 9月 | I3: 10月 | J3: 11月 | K3: 12月 | L3: 1月 | M3: 2月 | N3: 3月 | O3: 4月 | P3: 5月 | Q3: 6月
A4: セッション数 | B4: 764 | C4: 1778 | D4: 972 | E4: 1028 | F4: 3160 | G4: 1281 | H4: 1652 | I4: 1120 | J4: 1551 | K4: 1613 | L4: 1364 | M4: 1222 | N4: 1317 | O4: 1450 | P4: 1172
A5: セッション数｜施策種別｜テーマ | F5: ・テレビ放映のお知らせ | H5: ・実績事例：株式会社メガネトップ 様 ・実績事例：ヤクルト球団株式会社 様 ・実績事例：イオンリテール株式会社 様 ・実績事例：株式会社フジオフードシステム 様 ・実績事例：ピザハット様：2025年福袋セット ・実績事例：ブロンコビリー様 | I5: ・実績事例：株式会社タカキベーカリー様 | J5: ・コラムNo.6 ・実績事例：ファンケル様：サマーCP ・お知らせ｜新着コラム紹介 | K5: コラムNo.11 ・実績事例：天下一品様 ・お知らせ：事例天一食品商事 様 | L5: ・TOP、サービスLP（SP、ブランディング、OEM/ODM）ページのデザイン刷新 ・コラムNo.11 ・お知らせ：コラムNo.7 ・お知らせ：コラムNo.11 | M5: ・コラムNo.2｜リライト ・実績事例：カープ様：インタビュー ・お知らせ：パタンナーTV放映告知 ・お知らせ：コラムNo.2 ・お知らせ：実績事例（カープ様） | N5: ・コラムNo.7 ・コラムNo.10 ・コラムNo.13 ・コラムNo.15 ・ホワイトペーパー2｜簡易版 ・実績事例：ファンケル様：インタビュー ・実績事例：ブリヂストン様：インタビュー ・実績事例：壱番屋様：インタビュー ・お知らせ：コラムNo.10 ・お知らせ：コラムNo.13 ・お知らせ：実績事例（ファンケル様） ・お知らせ：実績事例（ブリヂストン様） ・お知らせ：実績事例（壱番屋様） | O5: ・コラムNo.5｜リライト ・コラムNo.14 ・ホワイトペーパー3｜簡易版 ・ホワイトペーパー4｜簡易版 ・お知らせ：コラムNo.5 ・お知らせ：コラムNo.14 | P5: ・コラムNo.12 ・コラムNo.16 ・お知らせ：コラムNo.12 ・お知らせ：コラムNo.15 ・お知らせ：コラムNo.16
A6: CV-WPDL（実数）
A7: CV-カタログDL（実数）
A8: CV-問い合わせ（実数）
A9: MQL数 | B9: 4 | C9: 6 | D9: 5 | E9: 12 | F9: 16 | G9: 25 | H9: 5 | I9: 15 | J9: 9 | K9: 24 | L9: 32 | M9: 39 | N9: 13 | O9: 5 | P9: 14
A10: MQL率 | B10: =B9/B4 -> 0.0052356021 | C10: =C9/C4 -> 0.0033745782 | D10: =D9/D4 -> 0.0051440329 | E10: =E9/E4 -> 0.011673152 | F10: =F9/F4 -> 0.0050632911 | G10: =G9/G4 -> 0.019516003 | H10: =H9/H4 -> 0.0030266344 | I10: =I9/I4 -> 0.013392857 | ... Q10: =Q9/Q4 -> #DIV/0!
A11: CV数｜施策種別｜テーマ | E11: ・メルマガNo.11 ・メルマガNo.12 | F11: ・内製メルマガNo.19 ・内製メルマガNo.20 ・内製メルマガNo.21 | I11: ・メルマガNo.15 ・メルマガNo.16 | J11: ・メルマガNo.17 | K11: ・メルマガNo.8｜リライト ・内製メルマガNo.24 | L11: ・メルマガNo.16 ・メルマガNo.18 ・内製メルマガNo.25 ・内製メルマガNo.26 | M11: ・メルマガNo.22 ・メルマガNo.23 ・内製メルマガNo.29 ・内製メルマガNo.30 | N11: ・内製メルマガNo.28 ・内製メルマガNo.31 | O11: ・メルマガNo.27 ・内製メルマガNo.32 | P11: ・メルマガNo.37 ・内製メルマガNo.38 | Q11: ・シナリオメール１～4（No.33～36） ・内製メルマガ｜No.40 ・内製メルマガ｜No.41
